Workbook

Sheet 使用说明
A1: 2026年足球世界杯竞猜活动 - 使用说明
A3: 📋 工作表说明
A4: 1. 【比赛赛程】- 包含所有104场比赛信息，管理员填写实际比赛结果
A5: 2. 【参与者填写】- 参与者在此填写每场比赛的比分预测
A6: 3. 【积分统计】- 自动计算每位参与者每场比赛的积分
A7: 4. 【总排名】- 自动生成参与者总积分排名
A9: 🎯 积分规则（新）
A10: • 预测准确比分：得 4 分
A11: • 只预测对胜负平关系：得 1 分
A12: • 胜负关系和比分都没猜中：得 0 分
A14: 📝 使用步骤
A15: 1. 在【比赛赛程】表中填写所有104场比赛的信息
... A26: • 本表格已预设104场比赛，涵盖全部赛程

Sheet 比赛赛程
A1: 比赛编号 | B1: 比赛阶段 | C1: 比赛日期 | D1: 队伍A | E1: 队伍B | F1: 实际比分A | G1: 实际比分B | H1: 实际胜负平
A2: 1 | B2: 小组赛A组第1轮 | C2: 2026-06-11 | D2: 待定A队1 | E2: 待定A队2
A3: 2 | B3: 小组赛A组第2轮 | C3: 2026-06-11 | D3: 待定A队1 | E3: 待定A队2
A4: 3 | B4: 小组赛A组第3轮 | C4: 2026-06-11 | D4: 待定A队1 | E4: 待定A队2
A5: 4 | B5: 小组赛A组第4轮 | C5: 2026-06-11 | D5: 待定A队1 | E5: 待定A队2
A6: 5 | B6: 小组赛A组第5轮 | C6: 2026-06-11 | D6: 待定A队1 | E6: 待定A队2
A7: 6 | B7: 小组赛A组第6轮 | C7: 2026-06-11 | D7: 待定A队1 | E7: 待定A队2
A8: 7 | B8: 小组赛B组第1轮 | C8: 2026-06-11 | D8: 待定B队1 | E8: 待定B队2
A9: 8 | B9: 小组赛B组第2轮 | C9: 2026-06-11 | D9: 待定B队1 | E9: 待定B队2
A10: 9 | B10: 小组赛B组第3轮 | C10: 2026-06-12 | D10: 待定B队1 | E10: 待定B队2
A11: 10 | B11: 小组赛B组第4轮 | C11: 2026-06-12 | D11: 待定B队1 | E11: 待定B队2
A12: 11 | B12: 小组赛B组第5轮 | C12: 2026-06-12 | D12: 待定B队1 | E12: 待定B队2
A13: 12 | B13: 小组赛B组第6轮 | C13: 2026-06-12 | D13: 待定B队1 | E13: 待定B队2
... A97: 96 | B97: Final | C97: 2026-07-14 | D97: 待定 | E97: 待定

Sheet 参与者填写
A1: 参与者姓名 | B1: 比赛1-队伍A比分 | C1: 比赛1-队伍B比分 | E1: 比赛2-队伍A比分 | F1: 比赛2-队伍B比分 | H1: 比赛3-队伍A比分 | I1: 比赛3-队伍B比分 | K1: 比赛4-队伍A比分 | L1: 比赛4-队伍B比分 | N1: 比赛5-队伍A比分 | O1: 比赛5-队伍B比分 | Q1: 比赛6-队伍A比分 | R1: 比赛6-队伍B比分 | T1: 比赛7-队伍A比分 | U1: 比赛7-队伍B比分 | W1: 比赛8-队伍A比分 | X1: 比赛8-队伍B比分 | Z1: 比赛9-队伍A比分 | AA1: 比赛9-队伍B比分 | AC1: 比赛10-队伍A比分 | AD1: 比赛10-队伍B比分 | AF1: 比赛11-队伍A比分 | AG1: 比赛11-队伍B比分 | AI1: 比赛12-队伍A比分 | AJ1: 比赛12-队伍B比分 | AL1: 比赛13-队伍A比分 | AM1: 比赛13-队伍B比分 | AO1: 比赛14-队伍A比分 | AP1: 比赛14-队伍B比分 | AR1: 比赛15-队伍A比分 | AS1: 比赛15-队伍B比分 | AU1: 比赛16-队伍A比分 | AV1: 比赛16-队伍B比分 | AX1: 比赛17-队伍A比分 | AY1: 比赛17-队伍B比分 | BA1: 比赛18-队伍A比分 | BB1: 比赛18-队伍B比分 | BD1: 比赛19-队伍A比分 | BE1: 比赛19-队伍B比分 | BG1: 比赛20-队伍A比分 | BH1: 比赛20-队伍B比分
A2: 张三 | B2: 0 | C2: 4 | E2: 0 | F2: 3 | H2: 1 | I2: 3 | K2: 2 | L2: 0 | N2: 1 | O2: 4 | Q2: 1 | R2: 1 | T2: 2 | U2: 2 | W2: 2 | X2: 2 | Z2: 3 | AA2: 2 | AC2: 1 | AD2: 4 | AF2: 4 | AG2: 3 | AI2: 3 | AJ2: 3 | AL2: 2 | AM2: 3 | AO2: 2 | AP2: 0 | AR2: 2 | AS2: 4 | AU2: 3 | AV2: 4 | AX2: 3 | AY2: 4 | BA2: 0 | BB2: 1 | BD2: 2 | BE2: 3 | BG2: 4 | BH2: 3
A3: 李四 | B3: 2 | C3: 3 | E3: 1 | F3: 0 | H3: 3 | I3: 0 | K3: 3 | L3: 3 | N3: 1 | O3: 4 | Q3: 4 | R3: 1 | T3: 3 | U3: 2 | W3: 1 | X3: 1 | Z3: 1 | AA3: 1 | AC3: 1 | AD3: 4 | AF3: 4 | AG3: 4 | AI3: 4 | AJ3: 0 | AL3: 0 | AM3: 2 | AO3: 3 | AP3: 1 | AR3: 2 | AS3: 3 | AU3: 1 | AV3: 0 | AX3: 3 | AY3: 2 | BA3: 4 | BB3: 2 | BD3: 2 | BE3: 2 | BG3: 0 | BH3: 4
A4: 王五 | B4: 4 | C4: 1 | E4: 2 | F4: 4 | H4: 0 | I4: 1 | K4: 0 | L4: 0 | N4: 2 | O4: 2 | Q4: 2 | R4: 1 | T4: 2 | U4: 0 | W4: 1 | X4: 4 | Z4: 4 | AA4: 4 | AC4: 4 | AD4: 2 | AF4: 0 | AG4: 1 | AI4: 2 | AJ4: 1 | AL4: 0 | AM4: 3 | AO4: 3 | AP4: 4 | AR4: 2 | AS4: 3 | AU4: 2 | AV4: 4 | AX4: 3 | AY4: 0 | BA4: 4 | BB4: 3 | BD4: 2 | BE4: 2 | BG4: 4 | BH4: 4
A5: 赵六 | B5: 1 | C5: 4 | E5: 0 | F5: 3 | H5: 4 | I5: 3 | K5: 3 | L5: 3 | N5: 4 | O5: 1 | Q5: 3 | R5: 3 | T5: 3 | U5: 3 | W5: 1 | X5: 0 | Z5: 4 | AA5: 1 | AC5: 3 | AD5: 2 | AF5: 2 | AG5: 3 | AI5: 2 | AJ5: 3 | AL5: 1 | AM5: 1 | AO5: 3 | AP5: 0 | AR5: 1 | AS5: 3 | AU5: 0 | AV5: 0 | AX5: 4 | AY5: 1 | BA5: 1 | BB5: 2 | BD5: 3 | BE5: 3 | BG5: 3 | BH5: 3

Sheet 积分统计
A1: 参与者姓名 | B1: 比赛1积分 | C1: 比赛2积分 | D1: 比赛3积分 | E1: 比赛4积分 | F1: 比赛5积分 | G1: 比赛6积分 | H1: 比赛7积分 | I1: 比赛8积分 | J1: 比赛9积分 | K1: 比赛10积分 | L1: 比赛11积分 | M1: 比赛12积分 | N1: 比赛13积分 | O1: 比赛14积分 | P1: 比赛15积分 | Q1: 比赛16积分 | R1: 比赛17积分 | S1: 比赛18积分 | T1: 比赛19积分 | U1: 比赛20积分 | V1: 比赛21积分 | W1: 比赛22积分 | X1: 比赛23积分 | Y1: 比赛24积分 | Z1: 比赛25积分 | AA1: 比赛26积分 | AB1: 比赛27积分 | AC1: 比赛28积分 | AD1: 比赛29积分 | AE1: 比赛30积分 | AF1: 比赛31积分 | AG1: 比赛32积分 | AH1: 比赛33积分 | AI1: 比赛34积分 | AJ1: 比赛35积分 | AK1: 比赛36积分 | AL1: 比赛37积分 | AM1: 比赛38积分 | AN1: 比赛39积分 | AO1: 比赛40积分 | AP1: 比赛41积分 | AQ1: 比赛42积分 | AR1: 比赛43积分 | AS1: 比赛44积分 | AT1: 比赛45积分 | AU1: 比赛46积分 | AV1: 比赛47积分 | AW1: 比赛48积分 | AX1: 比赛49积分 | AY1: 比赛50积分 | AZ1: 比赛51积分 | BA1: 比赛52积分 | BB1: 比赛53积分 | BC1: 比赛54积分 | BD1: 比赛55积分 | BE1: 比赛56积分 | BF1: 比赛57积分 | BG1: 比赛58积分 | BH1: 比赛59积分 | BI1: 比赛60积分 | BJ1: 比赛61积分 | BK1: 比赛62积分 | BL1: 比赛63积分 | BM1: 比赛64积分 | BN1: 比赛65积分 | BO1: 比赛66积分 | BP1: 比赛67积分 | BQ1: 比赛68积分 | BR1: 比赛69积分 | BS1: 比赛70积分 | BT1: 比赛71积分 | BU1: 比赛72积分 | BV1: 比赛73积分 | BW1: 比赛74积分 | BX1: 比赛75积分 | BY1: 比赛76积分 | BZ1: 比赛77积分 | CA1: 比赛78积分 | CB1: 比赛79积分 | CC1: 比赛80积分 | CD1: 比赛81积分 | CE1: 比赛82积分 | CF1: 比赛83积分 | CG1: 比赛84积分 | CH1: 比赛85积分 | CI1: 比赛86积分 | CJ1: 比赛87积分 | CK1: 比赛88积分 | CL1: 比赛89积分 | CM1: 比赛90积分 | CN1: 比赛91积分 | CO1: 比赛92积分 | CP1: 比赛93积分 | CQ1: 比赛94积分 | CR1: 比赛95积分 | CS1: 比赛96积分 | CT1: 比赛97积分 | CU1: 比赛98积分 | CV1: 比赛99积分 | CW1: 比赛100积分 | CX1: 比赛101积分 | CY1: 比赛102积分 | CZ1: 比赛103积分 | DA1: 比赛104积分
A2: 张三 | B2: =IF(AND(参与者填写!B2<>"",参与者填写!C2<>""),IF(AND(参与者填写!B2=比赛赛程!F2,参与者填写!C2=比赛赛程!G2),4,IF(SIGN(参与者填写!B2-参与者填写!C2)=SIGN(比赛赛程!F2-比赛赛程!G2),1,0)),"") -> 0 | C2: =IF(AND(参与者填写!E2<>"",参与者填写!F2<>""),IF(AND(参与者填写!E2=比赛赛程!F3,参与者填写!F2=比赛赛程!G3),4,IF(SIGN(参与者填写!E2-参与者填写!F2)=SIGN(比赛赛程!F3-比赛赛程!G3),1,0)),"") -> 0 | D2: =IF(AND(参与者填写!H2<>"",参与者填写!I2<>""),IF(AND(参与者填写!H2=比赛赛程!F4,参与者填写!I2=比赛赛程!G4),4,IF(SIGN(参与者填写!H2-参与者填写!I2)=SIGN(比赛赛程!F4-比赛赛程!G4),1,0)),"") -> 0 | E2: =IF(AND(参与者填写!K2<>"",参与者填写!L2<>""),IF(AND(参与者填写!K2=比赛赛程!F5,参与者填写!L2=比赛赛程!G5),4,IF(SIGN(参与者填写!K2-参与者填写!L2)=SIGN(比赛赛程!F5-比赛赛程!G5),1,0)),"") -> 0 | F2: =IF(AND(参与者填写!N2<>"",参与者填写!O2<>""),IF(AND(参与者填写!N2=比赛赛程!F6,参与者填写!O2=比赛赛程!G6),4,IF(SIGN(参与者填写!N2-参与者填写!O2)=SIGN(比赛赛程!F6-比赛赛程!G6),1,0)),"") -> 0 | G2: =IF(AND(参与者填写!Q2<>"",参与者填写!R2<>""),IF(AND(参与者填写!Q2=比赛赛程!F7,参与者填写!R2=比赛赛程!G7),4,IF(SIGN(参与者填写!Q2-参与者填写!R2)=SIGN(比赛赛程!F7-比赛赛程!G7),1,0)),"") -> 1 | H2: =IF(AND(参与者填写!T2<>"",参与者填写!U2<>""),IF(AND(参与者填写!T2=比赛赛程!F8,参与者填写!U2=比赛赛程!G8),4,IF(SIGN(参与者填写!T2-参与者填写!U2)=SIGN(比赛赛程!F8-比赛赛程!G8),1,0)),"") -> 1 | I2: =IF(AND(参与者填写!W2<>"",参与者填写!X2<>""),IF(AND(参与者填写!W2=比赛赛程!F9,参与者填写!X2=比赛赛程!G9),4,IF(SIGN(参与者填写!W2-参与者填写!X2)=SIGN(比赛赛程!F9-比赛赛程!G9),1,0)),"") -> 1 | J2: =IF(AND(参与者填写!Z2<>"",参与者填写!AA2<>""),IF(AND(参与者填写!Z2=比赛赛程!F10,参与者填写!AA2=比赛赛程!G10),4,IF(SIGN(参与者填写!Z2-参与者填写!AA2)=SIGN(比赛赛程!F10-比赛赛程!G10),1,0)),"") -> 0 | K2: =IF(AND(参与者填写!AC2<>"",参与者填写!AD2<>""),IF(AND(参与者填写!AC2=比赛赛程!F11,参与者填写!AD2=比赛赛程!G11),4,IF(SIGN(参与者填写!AC2-参与者填写!AD2)=SIGN(比赛赛程!F11-比赛赛程!G11),1,0)),"") -> 0 | L2: =IF(AND(参与者填写!AF2<>"",参与者填写!AG2<>""),IF(AND(参与者填写!AF2=比赛赛程!F12,参与者填写!AG2=比赛赛程!G12),4,IF(SIGN(参与者填写!AF2-参与者填写!AG2)=SIGN(比赛赛程!F12-比赛赛程!G12),1,0)),"") -> 0 | M2: =IF(AND(参与者填写!AI2<>"",参与者填写!AJ2<>""),IF(AND(参与者填写!AI2=比赛赛程!F13,参与者填写!AJ2=比赛赛程!G13),4,IF(SIGN(参与者填写!AI2-参与者填写!AJ2)=SIGN(比赛赛程!F13-比赛赛程!G13),1,0)),"") -> 1 | N2: =IF(AND(参与者填写!AL2<>"",参与者填写!AM2<>""),IF(AND(参与者填写!AL2=比赛赛程!F14,参与者填写!AM2=比赛赛程!G14),4,IF(SIGN(参与者填写!AL2-参与者填写!AM2)=SIGN(比赛赛程!F14-比赛赛程!G14),1,0)),"") -> 0 | O2: =IF(AND(参与者填写!AO2<>"",参与者填写!AP2<>""),IF(AND(参与者填写!AO2=比赛赛程!F15,参与者填写!AP2=比赛赛程!G15),4,IF(SIGN(参与者填写!AO2-参与者填写!AP2)=SIGN(比赛赛程!F15-比赛赛程!G15),1,0)),"") -> 0 | P2: =IF(AND(参与者填写!AR2<>"",参与者填写!AS2<>""),IF(AND(参与者填写!AR2=比赛赛程!F16,参与者填写!AS2=比赛赛程!G16),4,IF(SIGN(参与者填写!AR2-参与者填写!AS2)=SIGN(比赛赛程!F16-比赛赛程!G16),1,0)),"") -> 0 | Q2: =IF(AND(参与者填写!AU2<>"",参与者填写!AV2<>""),IF(AND(参与者填写!AU2=比赛赛程!F17,参与者填写!AV2=比赛赛程!G17),4,IF(SIGN(参与者填写!AU2-参与者填写!AV2)=SIGN(比赛赛程!F17-比赛赛程!G17),1,0)),"") -> 0 | R2: =IF(AND(参与者填写!AX2<>"",参与者填写!AY2<>""),IF(AND(参与者填写!AX2=比赛赛程!F18,参与者填写!AY2=比赛赛程!G18),4,IF(SIGN(参与者填写!AX2-参与者填写!AY2)=SIGN(比赛赛程!F18-比赛赛程!G18),1,0)),"") -> 0 | S2: =IF(AND(参与者填写!BA2<>"",参与者填写!BB2<>""),IF(AND(参与者填写!BA2=比赛赛程!F19,参与者填写!BB2=比赛赛程!G19),4,IF(SIGN(参与者填写!BA2-参与者填写!BB2)=SIGN(比赛赛程!F19-比赛赛程!G19),1,0)),"") -> 0 | T2: =IF(AND(参与者填写!BD2<>"",参与者填写!BE2<>""),IF(AND(参与者填写!BD2=比赛赛程!F20,参与者填写!BE2=比赛赛程!G20),4,IF(SIGN(参与者填写!BD2-参与者填写!BE2)=SIGN(比赛赛程!F20-比赛赛程!G20),1,0)),"") -> 0 | U2: =IF(AND(参与者填写!BG2<>"",参与者填写!BH2<>""),IF(AND(参与者填写!BG2=比赛赛程!F21,参与者填写!BH2=比赛赛程!G21),4,IF(SIGN(参与者填写!BG2-参与者填写!BH2)=SIGN(比赛赛程!F21-比赛赛程!G21),1,0)),"") -> 0 | V2: =IF(AND(参与者填写!BJ2<>"",参与者填写!BK2<>""),IF(AND(参与者填写!BJ2=比赛赛程!F22,参与者填写!BK2=比赛赛程!G22),4,IF(SIGN(参与者填写!BJ2-参与者填写!BK2)=SIGN(比赛赛程!F22-比赛赛程!G22),1,0)),"") | W2: =IF(AND(参与者填写!BM2<>"",参与者填写!BN2<>""),IF(AND(参与者填写!BM2=比赛赛程!F23,参与者填写!BN2=比赛赛程!G23),4,IF(SIGN(参与者填写!BM2-参与者填写!BN2)=SIGN(比赛赛程!F23-比赛赛程!G23),1,0)),"") | X2: =IF(AND(参与者填写!BP2<>"",参与者填写!BQ2<>""),IF(AND(参与者填写!BP2=比赛赛程!F24,参与者填写!BQ2=比赛赛程!G24),4,IF(SIGN(参与者填写!BP2-参与者填写!BQ2)=SIGN(比赛赛程!F24-比赛赛程!G24),1,0)),"") | Y2: =IF(AND(参与者填写!BS2<>"",参与者填写!BT2<>""),IF(AND(参与者填写!BS2=比赛赛程!F25,参与者填写!BT2=比赛赛程!G25),4,IF(SIGN(参与者填写!BS2-参与者填写!BT2)=SIGN(比赛赛程!F25-比赛赛程!G25),1,0)),"") | Z2: =IF(AND(参与者填写!BV2<>"",参与者填写!BW2<>""),IF(AND(参与者填写!BV2=比赛赛程!F26,参与者填写!BW2=比赛赛程!G26),4,IF(SIGN(参与者填写!BV2-参与者填写!BW2)=SIGN(比赛赛程!F26-比赛赛程!G26),1,0)),"") | AA2: =IF(AND(参与者填写!BY2<>"",参与者填写!BZ2<>""),IF(AND(参与者填写!BY2=比赛赛程!F27,参与者填写!BZ2=比赛赛程!G27),4,IF(SIGN(参与者填写!BY2-参与者填写!BZ2)=SIGN(比赛赛程!F27-比赛赛程!G27),1,0)),"") | AB2: =IF(AND(参与者填写!CB2<>"",参与者填写!CC2<>""),IF(AND(参与者填写!CB2=比赛赛程!F28,参与者填写!CC2=比赛赛程!G28),4,IF(SIGN(参与者填写!CB2-参与者填写!CC2)=SIGN(比赛赛程!F28-比赛赛程!G28),1,0)),"") | AC2: =IF(AND(参与者填写!CE2<>"",参与者填写!CF2<>""),IF(AND(参与者填写!CE2=比赛赛程!F29,参与者填写!CF2=比赛赛程!G29),4,IF(SIGN(参与者填写!CE2-参与者填写!CF2)=SIGN(比赛赛程!F29-比赛赛程!G29),1,0)),"") | AD2: =IF(AND(参与者填写!CH2<>"",参与者填写!CI2<>""),IF(AND(参与者填写!CH2=比赛赛程!F30,参与者填写!CI2=比赛赛程!G30),4,IF(SIGN(参与者填写!CH2-参与者填写!CI2)=SIGN(比赛赛程!F30-比赛赛程!G30),1,0)),"") | AE2: =IF(AND(参与者填写!CK2<>"",参与者填写!CL2<>""),IF(AND(参与者填写!CK2=比赛赛程!F31,参与者填写!CL2=比赛赛程!G31),4,IF(SIGN(参与者填写!CK2-参与者填写!CL2)=SIGN(比赛赛程!F31-比赛赛程!G31),1,0)),"") | AF2: =IF(AND(参与者填写!CN2<>"",参与者填写!CO2<>""),IF(AND(参与者填写!CN2=比赛赛程!F32,参与者填写!CO2=比赛赛程!G32),4,IF(SIGN(参与者填写!CN2-参与者填写!CO2)=SIGN(比赛赛程!F32-比赛赛程!G32),1,0)),"") | AG2: =IF(AND(参与者填写!CQ2<>"",参与者填写!CR2<>""),IF(AND(参与者填写!CQ2=比赛赛程!F33,参与者填写!CR2=比赛赛程!G33),4,IF(SIGN(参与者填写!CQ2-参与者填写!CR2)=SIGN(比赛赛程!F33-比赛赛程!G33),1,0)),"") | AH2: =IF(AND(参与者填写!CT2<>"",参与者填写!CU2<>""),IF(AND(参与者填写!CT2=比赛赛程!F34,参与者填写!CU2=比赛赛程!G34),4,IF(SIGN(参与者填写!CT2-参与者填写!CU2)=SIGN(比赛赛程!F34-比赛赛程!G34),1,0)),"") | AI2: =IF(AND(参与者填写!CW2<>"",参与者填写!CX2<>""),IF(AND(参与者填写!CW2=比赛赛程!F35,参与者填写!CX2=比赛赛程!G35),4,IF(SIGN(参与者填写!CW2-参与者填写!CX2)=SIGN(比赛赛程!F35-比赛赛程!G35),1,0)),"") | AJ2: =IF(AND(参与者填写!CZ2<>"",参与者填写!DA2<>""),IF(AND(参与者填写!CZ2=比赛赛程!F36,参与者填写!DA2=比赛赛程!G36),4,IF(SIGN(参与者填写!CZ2-参与者填写!DA2)=SIGN(比赛赛程!F36-比赛赛程!G36),1,0)),"") | AK2: =IF(AND(参与者填写!DC2<>"",参与者填写!DD2<>""),IF(AND(参与者填写!DC2=比赛赛程!F37,参与者填写!DD2=比赛赛程!G37),4,IF(SIGN(参与者填写!DC2-参与者填写!DD2)=SIGN(比赛赛程!F37-比赛赛程!G37),1,0)),"") | AL2: =IF(AND(参与者填写!DF2<>"",参与者填写!DG2<>""),IF(AND(参与者填写!DF2=比赛赛程!F38,参与者填写!DG2=比赛赛程!G38),4,IF(SIGN(参与者填写!DF2-参与者填写!DG2)=SIGN(比赛赛程!F38-比赛赛程!G38),1,0)),"") | AM2: =IF(AND(参与者填写!DI2<>"",参与者填写!DJ2<>""),IF(AND(参与者填写!DI2=比赛赛程!F39,参与者填写!DJ2=比赛赛程!G39),4,IF(SIGN(参与者填写!DI2-参与者填写!DJ2)=SIGN(比赛赛程!F39-比赛赛程!G39),1,0)),"") | AN2: =IF(AND(参与者填写!DL2<>"",参与者填写!DM2<>""),IF(AND(参与者填写!DL2=比赛赛程!F40,参与者填写!DM2=比赛赛程!G40),4,IF(SIGN(参与者填写!DL2-参与者填写!DM2)=SIGN(比赛赛程!F40-比赛赛程!G40),1,0)),"") | AO2: =IF(AND(参与者填写!DO2<>"",参与者填写!DP2<>""),IF(AND(参与者填写!DO2=比赛赛程!F41,参与者填写!DP2=比赛赛程!G41),4,IF(SIGN(参与者填写!DO2-参与者填写!DP2)=SIGN(比赛赛程!F41-比赛赛程!G41),1,0)),"") | AP2: =IF(AND(参与者填写!DR2<>"",参与者填写!DS2<>""),IF(AND(参与者填写!DR2=比赛赛程!F42,参与者填写!DS2=比赛赛程!G42),4,IF(SIGN(参与者填写!DR2-参与者填写!DS2)=SIGN(比赛赛程!F42-比赛赛程!G42),1,0)),"") | AQ2: =IF(AND(参与者填写!DU2<>"",参与者填写!DV2<>""),IF(AND(参与者填写!DU2=比赛赛程!F43,参与者填写!DV2=比赛赛程!G43),4,IF(SIGN(参与者填写!DU2-参与者填写!DV2)=SIGN(比赛赛程!F43-比赛赛程!G43),1,0)),"") | AR2: =IF(AND(参与者填写!DX2<>"",参与者填写!DY2<>""),IF(AND(参与者填写!DX2=比赛赛程!F44,参与者填写!DY2=比赛赛程!G44),4,IF(SIGN(参与者填写!DX2-参与者填写!DY2)=SIGN(比赛赛程!F44-比赛赛程!G44),1,0)),"") | AS2: =IF(AND(参与者填写!EA2<>"",参与者填写!EB2<>""),IF(AND(参与者填写!EA2=比赛赛程!F45,参与者填写!EB2=比赛赛程!G45),4,IF(SIGN(参与者填写!EA2-参与者填写!EB2)=SIGN(比赛赛程!F45-比赛赛程!G45),1,0)),"") | AT2: =IF(AND(参与者填写!ED2<>"",参与者填写!EE2<>""),IF(AND(参与者填写!ED2=比赛赛程!F46,参与者填写!EE2=比赛赛程!G46),4,IF(SIGN(参与者填写!ED2-参与者填写!EE2)=SIGN(比赛赛程!F46-比赛赛程!G46),1,0)),"") | AU2: =IF(AND(参与者填写!EG2<>"",参与者填写!EH2<>""),IF(AND(参与者填写!EG2=比赛赛程!F47,参与者填写!EH2=比赛赛程!G47),4,IF(SIGN(参与者填写!EG2-参与者填写!EH2)=SIGN(比赛赛程!F47-比赛赛程!G47),1,0)),"") | AV2: =IF(AND(参与者填写!EJ2<>"",参与者填写!EK2<>""),IF(AND(参与者填写!EJ2=比赛赛程!F48,参与者填写!EK2=比赛赛程!G48),4,IF(SIGN(参与者填写!EJ2-参与者填写!EK2)=SIGN(比赛赛程!F48-比赛赛程!G48),1,0)),"") | AW2: =IF(AND(参与者填写!EM2<>"",参与者填写!EN2<>""),IF(AND(参与者填写!EM2=比赛赛程!F49,参与者填写!EN2=比赛赛程!G49),4,IF(SIGN(参与者填写!EM2-参与者填写!EN2)=SIGN(比赛赛程!F49-比赛赛程!G49),1,0)),"") | AX2: =IF(AND(参与者填写!EP2<>"",参与者填写!EQ2<>""),IF(AND(参与者填写!EP2=比赛赛程!F50,参与者填写!EQ2=比赛赛程!G50),4,IF(SIGN(参与者填写!EP2-参与者填写!EQ2)=SIGN(比赛赛程!F50-比赛赛程!G50),1,0)),"") | AY2: =IF(AND(参与者填写!ES2<>"",参与者填写!ET2<>""),IF(AND(参与者填写!ES2=比赛赛程!F51,参与者填写!ET2=比赛赛程!G51),4,IF(SIGN(参与者填写!ES2-参与者填写!ET2)=SIGN(比赛赛程!F51-比赛赛程!G51),1,0)),"") | AZ2: =IF(AND(参与者填写!EV2<>"",参与者填写!EW2<>""),IF(AND(参与者填写!EV2=比赛赛程!F52,参与者填写!EW2=比赛赛程!G52),4,IF(SIGN(参与者填写!EV2-参与者填写!EW2)=SIGN(比赛赛程!F52-比赛赛程!G52),1,0)),"") | BA2: =IF(AND(参与者填写!EY2<>"",参与者填写!EZ2<>""),IF(AND(参与者填写!EY2=比赛赛程!F53,参与者填写!EZ2=比赛赛程!G53),4,IF(SIGN(参与者填写!EY2-参与者填写!EZ2)=SIGN(比赛赛程!F53-比赛赛程!G53),1,0)),"") | BB2: =IF(AND(参与者填写!FB2<>"",参与者填写!FC2<>""),IF(AND(参与者填写!FB2=比赛赛程!F54,参与者填写!FC2=比赛赛程!G54),4,IF(SIGN(参与者填写!FB2-参与者填写!FC2)=SIGN(比赛赛程!F54-比赛赛程!G54),1,0)),"") | BC2: =IF(AND(参与者填写!FE2<>"",参与者填写!FF2<>""),IF(AND(参与者填写!FE2=比赛赛程!F55,参与者填写!FF2=比赛赛程!G55),4,IF(SIGN(参与者填写!FE2-参与者填写!FF2)=SIGN(比赛赛程!F55-比赛赛程!G55),1,0)),"") | BD2: =IF(AND(参与者填写!FH2<>"",参与者填写!FI2<>""),IF(AND(参与者填写!FH2=比赛赛程!F56,参与者填写!FI2=比赛赛程!G56),4,IF(SIGN(参与者填写!FH2-参与者填写!FI2)=SIGN(比赛赛程!F56-比赛赛程!G56),1,0)),"") | BE2: =IF(AND(参与者填写!FK2<>"",参与者填写!FL2<>""),IF(AND(参与者填写!FK2=比赛赛程!F57,参与者填写!FL2=比赛赛程!G57),4,IF(SIGN(参与者填写!FK2-参与者填写!FL2)=SIGN(比赛赛程!F57-比赛赛程!G57),1,0)),"") | BF2: =IF(AND(参与者填写!FN2<>"",参与者填写!FO2<>""),IF(AND(参与者填写!FN2=比赛赛程!F58,参与者填写!FO2=比赛赛程!G58),4,IF(SIGN(参与者填写!FN2-参与者填写!FO2)=SIGN(比赛赛程!F58-比赛赛程!G58),1,0)),"") | BG2: =IF(AND(参与者填写!FQ2<>"",参与者填写!FR2<>""),IF(AND(参与者填写!FQ2=比赛赛程!F59,参与者填写!FR2=比赛赛程!G59),4,IF(SIGN(参与者填写!FQ2-参与者填写!FR2)=SIGN(比赛赛程!F59-比赛赛程!G59),1,0)),"") | BH2: =IF(AND(参与者填写!FT2<>"",参与者填写!FU2<>""),IF(AND(参与者填写!FT2=比赛赛程!F60,参与者填写!FU2=比赛赛程!G60),4,IF(SIGN(参与者填写!FT2-参与者填写!FU2)=SIGN(比赛赛程!F60-比赛赛程!G60),1,0)),"") | BI2: =IF(AND(参与者填写!FW2<>"",参与者填写!FX2<>""),IF(AND(参与者填写!FW2=比赛赛程!F61,参与者填写!FX2=比赛赛程!G61),4,IF(SIGN(参与者填写!FW2-参与者填写!FX2)=SIGN(比赛赛程!F61-比赛赛程!G61),1,0)),"") | BJ2: =IF(AND(参与者填写!FZ2<>"",参与者填写!GA2<>""),IF(AND(参与者填写!FZ2=比赛赛程!F62,参与者填写!GA2=比赛赛程!G62),4,IF(SIGN(参与者填写!FZ2-参与者填写!GA2)=SIGN(比赛赛程!F62-比赛赛程!G62),1,0)),"") | BK2: =IF(AND(参与者填写!GC2<>"",参与者填写!GD2<>""),IF(AND(参与者填写!GC2=比赛赛程!F63,参与者填写!GD2=比赛赛程!G63),4,IF(SIGN(参与者填写!GC2-参与者填写!GD2)=SIGN(比赛赛程!F63-比赛赛程!G63),1,0)),"") | BL2: =IF(AND(参与者填写!GF2<>"",参与者填写!GG2<>""),IF(AND(参与者填写!GF2=比赛赛程!F64,参与者填写!GG2=比赛赛程!G64),4,IF(SIGN(参与者填写!GF2-参与者填写!GG2)=SIGN(比赛赛程!F64-比赛赛程!G64),1,0)),"") | BM2: =IF(AND(参与者填写!GI2<>"",参与者填写!GJ2<>""),IF(AND(参与者填写!GI2=比赛赛程!F65,参与者填写!GJ2=比赛赛程!G65),4,IF(SIGN(参与者填写!GI2-参与者填写!GJ2)=SIGN(比赛赛程!F65-比赛赛程!G65),1,0)),"") | BN2: =IF(AND(参与者填写!GL2<>"",参与者填写!GM2<>""),IF(AND(参与者填写!GL2=比赛赛程!F66,参与者填写!GM2=比赛赛程!G66),4,IF(SIGN(参与者填写!GL2-参与者填写!GM2)=SIGN(比赛赛程!F66-比赛赛程!G66),1,0)),"") | BO2: =IF(AND(参与者填写!GO2<>"",参与者填写!GP2<>""),IF(AND(参与者填写!GO2=比赛赛程!F67,参与者填写!GP2=比赛赛程!G67),4,IF(SIGN(参与者填写!GO2-参与者填写!GP2)=SIGN(比赛赛程!F67-比赛赛程!G67),1,0)),"") | BP2: =IF(AND(参与者填写!GR2<>"",参与者填写!GS2<>""),IF(AND(参与者填写!GR2=比赛赛程!F68,参与者填写!GS2=比赛赛程!G68),4,IF(SIGN(参与者填写!GR2-参与者填写!GS2)=SIGN(比赛赛程!F68-比赛赛程!G68),1,0)),"") | BQ2: =IF(AND(参与者填写!GU2<>"",参与者填写!GV2<>""),IF(AND(参与者填写!GU2=比赛赛程!F69,参与者填写!GV2=比赛赛程!G69),4,IF(SIGN(参与者填写!GU2-参与者填写!GV2)=SIGN(比赛赛程!F69-比赛赛程!G69),1,0)),"") | BR2: =IF(AND(参与者填写!GX2<>"",参与者填写!GY2<>""),IF(AND(参与者填写!GX2=比赛赛程!F70,参与者填写!GY2=比赛赛程!G70),4,IF(SIGN(参与者填写!GX2-参与者填写!GY2)=SIGN(比赛赛程!F70-比赛赛程!G70),1,0)),"") | BS2: =IF(AND(参与者填写!HA2<>"",参与者填写!HB2<>""),IF(AND(参与者填写!HA2=比赛赛程!F71,参与者填写!HB2=比赛赛程!G71),4,IF(SIGN(参与者填写!HA2-参与者填写!HB2)=SIGN(比赛赛程!F71-比赛赛程!G71),1,0)),"") | BT2: =IF(AND(参与者填写!HD2<>"",参与者填写!HE2<>""),IF(AND(参与者填写!HD2=比赛赛程!F72,参与者填写!HE2=比赛赛程!G72),4,IF(SIGN(参与者填写!HD2-参与者填写!HE2)=SIGN(比赛赛程!F72-比赛赛程!G72),1,0)),"") | BU2: =IF(AND(参与者填写!HG2<>"",参与者填写!HH2<>""),IF(AND(参与者填写!HG2=比赛赛程!F73,参与者填写!HH2=比赛赛程!G73),4,IF(SIGN(参与者填写!HG2-参与者填写!HH2)=SIGN(比赛赛程!F73-比赛赛程!G73),1,0)),"") | BV2: =IF(AND(参与者填写!HJ2<>"",参与者填写!HK2<>""),IF(AND(参与者填写!HJ2=比赛赛程!F74,参与者填写!HK2=比赛赛程!G74),4,IF(SIGN(参与者填写!HJ2-参与者填写!HK2)=SIGN(比赛赛程!F74-比赛赛程!G74),1,0)),"") | BW2: =IF(AND(参与者填写!HM2<>"",参与者填写!HN2<>""),IF(AND(参与者填写!HM2=比赛赛程!F75,参与者填写!HN2=比赛赛程!G75),4,IF(SIGN(参与者填写!HM2-参与者填写!HN2)=SIGN(比赛赛程!F75-比赛赛程!G75),1,0)),"") | BX2: =IF(AND(参与者填写!HP2<>"",参与者填写!HQ2<>""),IF(AND(参与者填写!HP2=比赛赛程!F76,参与者填写!HQ2=比赛赛程!G76),4,IF(SIGN(参与者填写!HP2-参与者填写!HQ2)=SIGN(比赛赛程!F76-比赛赛程!G76),1,0)),"") | BY2: =IF(AND(参与者填写!HS2<>"",参与者填写!HT2<>""),IF(AND(参与者填写!HS2=比赛赛程!F77,参与者填写!HT2=比赛赛程!G77),4,IF(SIGN(参与者填写!HS2-参与者填写!HT2)=SIGN(比赛赛程!F77-比赛赛程!G77),1,0)),"") | BZ2: =IF(AND(参与者填写!HV2<>"",参与者填写!HW2<>""),IF(AND(参与者填写!HV2=比赛赛程!F78,参与者填写!HW2=比赛赛程!G78),4,IF(SIGN(参与者填写!HV2-参与者填写!HW2)=SIGN(比赛赛程!F78-比赛赛程!G78),1,0)),"") | CA2: =IF(AND(参与者填写!HY2<>"",参与者填写!HZ2<>""),IF(AND(参与者填写!HY2=比赛赛程!F79,参与者填写!HZ2=比赛赛程!G79),4,IF(SIGN(参与者填写!HY2-参与者填写!HZ2)=SIGN(比赛赛程!F79-比赛赛程!G79),1,0)),"") | CB2: =IF(AND(参与者填写!IB2<>"",参与者填写!IC2<>""),IF(AND(参与者填写!IB2=比赛赛程!F80,参与者填写!IC2=比赛赛程!G80),4,IF(SIGN(参与者填写!IB2-参与者填写!IC2)=SIGN(比赛赛程!F80-比赛赛程!G80),1,0)),"") | CC2: =IF(AND(参与者填写!IE2<>"",参与者填写!IF2<>""),IF(AND(参与者填写!IE2=比赛赛程!F81,参与者填写!IF2=比赛赛程!G81),4,IF(SIGN(参与者填写!IE2-参与者填写!IF2)=SIGN(比赛赛程!F81-比赛赛程!G81),1,0)),"") | CD2: =IF(AND(参与者填写!IH2<>"",参与者填写!II2<>""),IF(AND(参与者填写!IH2=比赛赛程!F82,参与者填写!II2=比赛赛程!G82),4,IF(SIGN(参与者填写!IH2-参与者填写!II2)=SIGN(比赛赛程!F82-比赛赛程!G82),1,0)),"") | CE2: =IF(AND(参与者填写!IK2<>"",参与者填写!IL2<>""),IF(AND(参与者填写!IK2=比赛赛程!F83,参与者填写!IL2=比赛赛程!G83),4,IF(SIGN(参与者填写!IK2-参与者填写!IL2)=SIGN(比赛赛程!F83-比赛赛程!G83),1,0)),"") | CF2: =IF(AND(参与者填写!IN2<>"",参与者填写!IO2<>""),IF(AND(参与者填写!IN2=比赛赛程!F84,参与者填写!IO2=比赛赛程!G84),4,IF(SIGN(参与者填写!IN2-参与者填写!IO2)=SIGN(比赛赛程!F84-比赛赛程!G84),1,0)),"") | CG2: =IF(AND(参与者填写!IQ2<>"",参与者填写!IR2<>""),IF(AND(参与者填写!IQ2=比赛赛程!F85,参与者填写!IR2=比赛赛程!G85),4,IF(SIGN(参与者填写!IQ2-参与者填写!IR2)=SIGN(比赛赛程!F85-比赛赛程!G85),1,0)),"") | CH2: =IF(AND(参与者填写!IT2<>"",参与者填写!IU2<>""),IF(AND(参与者填写!IT2=比赛赛程!F86,参与者填写!IU2=比赛赛程!G86),4,IF(SIGN(参与者填写!IT2-参与者填写!IU2)=SIGN(比赛赛程!F86-比赛赛程!G86),1,0)),"") | CI2: =IF(AND(参与者填写!IW2<>"",参与者填写!IX2<>""),IF(AND(参与者填写!IW2=比赛赛程!F87,参与者填写!IX2=比赛赛程!G87),4,IF(SIGN(参与者填写!IW2-参与者填写!IX2)=SIGN(比赛赛程!F87-比赛赛程!G87),1,0)),"") | CJ2: =IF(AND(参与者填写!IZ2<>"",参与者填写!JA2<>""),IF(AND(参与者填写!IZ2=比赛赛程!F88,参与者填写!JA2=比赛赛程!G88),4,IF(SIGN(参与者填写!IZ2-参与者填写!JA2)=SIGN(比赛赛程!F88-比赛赛程!G88),1,0)),"") | CK2: =IF(AND(参与者填写!JC2<>"",参与者填写!JD2<>""),IF(AND(参与者填写!JC2=比赛赛程!F89,参与者填写!JD2=比赛赛程!G89),4,IF(SIGN(参与者填写!JC2-参与者填写!JD2)=SIGN(比赛赛程!F89-比赛赛程!G89),1,0)),"") | CL2: =IF(AND(参与者填写!JF2<>"",参与者填写!JG2<>""),IF(AND(参与者填写!JF2=比赛赛程!F90,参与者填写!JG2=比赛赛程!G90),4,IF(SIGN(参与者填写!JF2-参与者填写!JG2)=SIGN(比赛赛程!F90-比赛赛程!G90),1,0)),"") | CM2: =IF(AND(参与者填写!JI2<>"",参与者填写!JJ2<>""),IF(AND(参与者填写!JI2=比赛赛程!F91,参与者填写!JJ2=比赛赛程!G91),4,IF(SIGN(参与者填写!JI2-参与者填写!JJ2)=SIGN(比赛赛程!F91-比赛赛程!G91),1,0)),"") | CN2: =IF(AND(参与者填写!JL2<>"",参与者填写!JM2<>""),IF(AND(参与者填写!JL2=比赛赛程!F92,参与者填写!JM2=比赛赛程!G92),4,IF(SIGN(参与者填写!JL2-参与者填写!JM2)=SIGN(比赛赛程!F92-比赛赛程!G92),1,0)),"") | CO2: =IF(AND(参与者填写!JO2<>"",参与者填写!JP2<>""),IF(AND(参与者填写!JO2=比赛赛程!F93,参与者填写!JP2=比赛赛程!G93),4,IF(SIGN(参与者填写!JO2-参与者填写!JP2)=SIGN(比赛赛程!F93-比赛赛程!G93),1,0)),"") | CP2: =IF(AND(参与者填写!JR2<>"",参与者填写!JS2<>""),IF(AND(参与者填写!JR2=比赛赛程!F94,参与者填写!JS2=比赛赛程!G94),4,IF(SIGN(参与者填写!JR2-参与者填写!JS2)=SIGN(比赛赛程!F94-比赛赛程!G94),1,0)),"") | CQ2: =IF(AND(参与者填写!JU2<>"",参与者填写!JV2<>""),IF(AND(参与者填写!JU2=比赛赛程!F95,参与者填写!JV2=比赛赛程!G95),4,IF(SIGN(参与者填写!JU2-参与者填写!JV2)=SIGN(比赛赛程!F95-比赛赛程!G95),1,0)),"") | CR2: =IF(AND(参与者填写!JX2<>"",参与者填写!JY2<>""),IF(AND(参与者填写!JX2=比赛赛程!F96,参与者填写!JY2=比赛赛程!G96),4,IF(SIGN(参与者填写!JX2-参与者填写!JY2)=SIGN(比赛赛程!F96-比赛赛程!G96),1,0)),"") | CS2: =IF(AND(参与者填写!KA2<>"",参与者填写!KB2<>""),IF(AND(参与者填写!KA2=比赛赛程!F97,参与者填写!KB2=比赛赛程!G97),4,IF(SIGN(参与者填写!KA2-参与者填写!KB2)=SIGN(比赛赛程!F97-比赛赛程!G97),1,0)),"") | CT2: =IF(AND(参与者填写!KD2<>"",参与者填写!KE2<>""),IF(AND(参与者填写!KD2=比赛赛程!F98,参与者填写!KE2=比赛赛程!G98),4,IF(SIGN(参与者填写!KD2-参与者填写!KE2)=SIGN(比赛赛程!F98-比赛赛程!G98),1,0)),"") | CU2: =IF(AND(参与者填写!KG2<>"",参与者填写!KH2<>""),IF(AND(参与者填写!KG2=比赛赛程!F99,参与者填写!KH2=比赛赛程!G99),4,IF(SIGN(参与者填写!KG2-参与者填写!KH2)=SIGN(比赛赛程!F99-比赛赛程!G99),1,0)),"") | CV2: =IF(AND(参与者填写!KJ2<>"",参与者填写!KK2<>""),IF(AND(参与者填写!KJ2=比赛赛程!F100,参与者填写!KK2=比赛赛程!G100),4,IF(SIGN(参与者填写!KJ2-参与者填写!KK2)=SIGN(比赛赛程!F100-比赛赛程!G100),1,0)),"") | CW2: =IF(AND(参与者填写!KM2<>"",参与者填写!KN2<>""),IF(AND(参与者填写!KM2=比赛赛程!F101,参与者填写!KN2=比赛赛程!G101),4,IF(SIGN(参与者填写!KM2-参与者填写!KN2)=SIGN(比赛赛程!F101-比赛赛程!G101),1,0)),"") | CX2: =IF(AND(参与者填写!KP2<>"",参与者填写!KQ2<>""),IF(AND(参与者填写!KP2=比赛赛程!F102,参与者填写!KQ2=比赛赛程!G102),4,IF(SIGN(参与者填写!KP2-参与者填写!KQ2)=SIGN(比赛赛程!F102-比赛赛程!G102),1,0)),"") | CY2: =IF(AND(参与者填写!KS2<>"",参与者填写!KT2<>""),IF(AND(参与者填写!KS2=比赛赛程!F103,参与者填写!KT2=比赛赛程!G103),4,IF(SIGN(参与者填写!KS2-参与者填写!KT2)=SIGN(比赛赛程!F103-比赛赛程!G103),1,0)),"") | CZ2: =IF(AND(参与者填写!KV2<>"",参与者填写!KW2<>""),IF(AND(参与者填写!KV2=比赛赛程!F104,参与者填写!KW2=比赛赛程!G104),4,IF(SIGN(参与者填写!KV2-参与者填写!KW2)=SIGN(比赛赛程!F104-比赛赛程!G104),1,0)),"") | DA2: =IF(AND(参与者填写!KY2<>"",参与者填写!KZ2<>""),IF(AND(参与者填写!KY2=比赛赛程!F105,参与者填写!KZ2=比赛赛程!G105),4,IF(SIGN(参与者填写!KY2-参与者填写!KZ2)=SIGN(比赛赛程!F105-比赛赛程!G105),1,0)),"")
A3: 李四 | B3: =IF(AND(参与者填写!B3<>"",参与者填写!C3<>""),IF(AND(参与者填写!B3=比赛赛程!F2,参与者填写!C3=比赛赛程!G2),4,IF(SIGN(参与者填写!B3-参与者填写!C3)=SIGN(比赛赛程!F2-比赛赛程!G2),1,0)),"") -> 0 | C3: =IF(AND(参与者填写!E3<>"",参与者填写!F3<>""),IF(AND(参与者填写!E3=比赛赛程!F3,参与者填写!F3=比赛赛程!G3),4,IF(SIGN(参与者填写!E3-参与者填写!F3)=SIGN(比赛赛程!F3-比赛赛程!G3),1,0)),"") -> 0 | D3: =IF(AND(参与者填写!H3<>"",参与者填写!I3<>""),IF(AND(参与者填写!H3=比赛赛程!F4,参与者填写!I3=比赛赛程!G4),4,IF(SIGN(参与者填写!H3-参与者填写!I3)=SIGN(比赛赛程!F4-比赛赛程!G4),1,0)),"") -> 0 | E3: =IF(AND(参与者填写!K3<>"",参与者填写!L3<>""),IF(AND(参与者填写!K3=比赛赛程!F5,参与者填写!L3=比赛赛程!G5),4,IF(SIGN(参与者填写!K3-参与者填写!L3)=SIGN(比赛赛程!F5-比赛赛程!G5),1,0)),"") -> 1 | F3: =IF(AND(参与者填写!N3<>"",参与者填写!O3<>""),IF(AND(参与者填写!N3=比赛赛程!F6,参与者填写!O3=比赛赛程!G6),4,IF(SIGN(参与者填写!N3-参与者填写!O3)=SIGN(比赛赛程!F6-比赛赛程!G6),1,0)),"") -> 0 | G3: =IF(AND(参与者填写!Q3<>"",参与者填写!R3<>""),IF(AND(参与者填写!Q3=比赛赛程!F7,参与者填写!R3=比赛赛程!G7),4,IF(SIGN(参与者填写!Q3-参与者填写!R3)=SIGN(比赛赛程!F7-比赛赛程!G7),1,0)),"") -> 0 | H3: =IF(AND(参与者填写!T3<>"",参与者填写!U3<>""),IF(AND(参与者填写!T3=比赛赛程!F8,参与者填写!U3=比赛赛程!G8),4,IF(SIGN(参与者填写!T3-参与者填写!U3)=SIGN(比赛赛程!F8-比赛赛程!G8),1,0)),"") -> 0 | I3: =IF(AND(参与者填写!W3<>"",参与者填写!X3<>""),IF(AND(参与者填写!W3=比赛赛程!F9,参与者填写!X3=比赛赛程!G9),4,IF(SIGN(参与者填写!W3-参与者填写!X3)=SIGN(比赛赛程!F9-比赛赛程!G9),1,0)),"") -> 1 | J3: =IF(AND(参与者填写!Z3<>"",参与者填写!AA3<>""),IF(AND(参与者填写!Z3=比赛赛程!F10,参与者填写!AA3=比赛赛程!G10),4,IF(SIGN(参与者填写!Z3-参与者填写!AA3)=SIGN(比赛赛程!F10-比赛赛程!G10),1,0)),"") -> 1 | K3: =IF(AND(参与者填写!AC3<>"",参与者填写!AD3<>""),IF(AND(参与者填写!AC3=比赛赛程!F11,参与者填写!AD3=比赛赛程!G11),4,IF(SIGN(参与者填写!AC3-参与者填写!AD3)=SIGN(比赛赛程!F11-比赛赛程!G11),1,0)),"") -> 0 | L3: =IF(AND(参与者填写!AF3<>"",参与者填写!AG3<>""),IF(AND(参与者填写!AF3=比赛赛程!F12,参与者填写!AG3=比赛赛程!G12),4,IF(SIGN(参与者填写!AF3-参与者填写!AG3)=SIGN(比赛赛程!F12-比赛赛程!G12),1,0)),"") -> 1 | M3: =IF(AND(参与者填写!AI3<>"",参与者填写!AJ3<>""),IF(AND(参与者填写!AI3=比赛赛程!F13,参与者填写!AJ3=比赛赛程!G13),4,IF(SIGN(参与者填写!AI3-参与者填写!AJ3)=SIGN(比赛赛程!F13-比赛赛程!G13),1,0)),"") -> 0 | N3: =IF(AND(参与者填写!AL3<>"",参与者填写!AM3<>""),IF(AND(参与者填写!AL3=比赛赛程!F14,参与者填写!AM3=比赛赛程!G14),4,IF(SIGN(参与者填写!AL3-参与者填写!AM3)=SIGN(比赛赛程!F14-比赛赛程!G14),1,0)),"") -> 0 | O3: =IF(AND(参与者填写!AO3<>"",参与者填写!AP3<>""),IF(AND(参与者填写!AO3=比赛赛程!F15,参与者填写!AP3=比赛赛程!G15),4,IF(SIGN(参与者填写!AO3-参与者填写!AP3)=SIGN(比赛赛程!F15-比赛赛程!G15),1,0)),"") -> 0 | P3: =IF(AND(参与者填写!AR3<>"",参与者填写!AS3<>""),IF(AND(参与者填写!AR3=比赛赛程!F16,参与者填写!AS3=比赛赛程!G16),4,IF(SIGN(参与者填写!AR3-参与者填写!AS3)=SIGN(比赛赛程!F16-比赛赛程!G16),1,0)),"") -> 0 | Q3: =IF(AND(参与者填写!AU3<>"",参与者填写!AV3<>""),IF(AND(参与者填写!AU3=比赛赛程!F17,参与者填写!AV3=比赛赛程!G17),4,IF(SIGN(参与者填写!AU3-参与者填写!AV3)=SIGN(比赛赛程!F17-比赛赛程!G17),1,0)),"") -> 0 | R3: =IF(AND(参与者填写!AX3<>"",参与者填写!AY3<>""),IF(AND(参与者填写!AX3=比赛赛程!F18,参与者填写!AY3=比赛赛程!G18),4,IF(SIGN(参与者填写!AX3-参与者填写!AY3)=SIGN(比赛赛程!F18-比赛赛程!G18),1,0)),"") -> 0 | S3: =IF(AND(参与者填写!BA3<>"",参与者填写!BB3<>""),IF(AND(参与者填写!BA3=比赛赛程!F19,参与者填写!BB3=比赛赛程!G19),4,IF(SIGN(参与者填写!BA3-参与者填写!BB3)=SIGN(比赛赛程!F19-比赛赛程!G19),1,0)),"") -> 0 | T3: =IF(AND(参与者填写!BD3<>"",参与者填写!BE3<>""),IF(AND(参与者填写!BD3=比赛赛程!F20,参与者填写!BE3=比赛赛程!G20),4,IF(SIGN(参与者填写!BD3-参与者填写!BE3)=SIGN(比赛赛程!F20-比赛赛程!G20),1,0)),"") -> 1 | U3: =IF(AND(参与者填写!BG3<>"",参与者填写!BH3<>""),IF(AND(参与者填写!BG3=比赛赛程!F21,参与者填写!BH3=比赛赛程!G21),4,IF(SIGN(参与者填写!BG3-参与者填写!BH3)=SIGN(比赛赛程!F21-比赛赛程!G21),1,0)),"") -> 0 | V3: =IF(AND(参与者填写!BJ3<>"",参与者填写!BK3<>""),IF(AND(参与者填写!BJ3=比赛赛程!F22,参与者填写!BK3=比赛赛程!G22),4,IF(SIGN(参与者填写!BJ3-参与者填写!BK3)=SIGN(比赛赛程!F22-比赛赛程!G22),1,0)),"") | W3: =IF(AND(参与者填写!BM3<>"",参与者填写!BN3<>""),IF(AND(参与者填写!BM3=比赛赛程!F23,参与者填写!BN3=比赛赛程!G23),4,IF(SIGN(参与者填写!BM3-参与者填写!BN3)=SIGN(比赛赛程!F23-比赛赛程!G23),1,0)),"") | X3: =IF(AND(参与者填写!BP3<>"",参与者填写!BQ3<>""),IF(AND(参与者填写!BP3=比赛赛程!F24,参与者填写!BQ3=比赛赛程!G24),4,IF(SIGN(参与者填写!BP3-参与者填写!BQ3)=SIGN(比赛赛程!F24-比赛赛程!G24),1,0)),"") | Y3: =IF(AND(参与者填写!BS3<>"",参与者填写!BT3<>""),IF(AND(参与者填写!BS3=比赛赛程!F25,参与者填写!BT3=比赛赛程!G25),4,IF(SIGN(参与者填写!BS3-参与者填写!BT3)=SIGN(比赛赛程!F25-比赛赛程!G25),1,0)),"") | Z3: =IF(AND(参与者填写!BV3<>"",参与者填写!BW3<>""),IF(AND(参与者填写!BV3=比赛赛程!F26,参与者填写!BW3=比赛赛程!G26),4,IF(SIGN(参与者填写!BV3-参与者填写!BW3)=SIGN(比赛赛程!F26-比赛赛程!G26),1,0)),"") | AA3: =IF(AND(参与者填写!BY3<>"",参与者填写!BZ3<>""),IF(AND(参与者填写!BY3=比赛赛程!F27,参与者填写!BZ3=比赛赛程!G27),4,IF(SIGN(参与者填写!BY3-参与者填写!BZ3)=SIGN(比赛赛程!F27-比赛赛程!G27),1,0)),"") | AB3: =IF(AND(参与者填写!CB3<>"",参与者填写!CC3<>""),IF(AND(参与者填写!CB3=比赛赛程!F28,参与者填写!CC3=比赛赛程!G28),4,IF(SIGN(参与者填写!CB3-参与者填写!CC3)=SIGN(比赛赛程!F28-比赛赛程!G28),1,0)),"") | AC3: =IF(AND(参与者填写!CE3<>"",参与者填写!CF3<>""),IF(AND(参与者填写!CE3=比赛赛程!F29,参与者填写!CF3=比赛赛程!G29),4,IF(SIGN(参与者填写!CE3-参与者填写!CF3)=SIGN(比赛赛程!F29-比赛赛程!G29),1,0)),"") | AD3: =IF(AND(参与者填写!CH3<>"",参与者填写!CI3<>""),IF(AND(参与者填写!CH3=比赛赛程!F30,参与者填写!CI3=比赛赛程!G30),4,IF(SIGN(参与者填写!CH3-参与者填写!CI3)=SIGN(比赛赛程!F30-比赛赛程!G30),1,0)),"") | AE3: =IF(AND(参与者填写!CK3<>"",参与者填写!CL3<>""),IF(AND(参与者填写!CK3=比赛赛程!F31,参与者填写!CL3=比赛赛程!G31),4,IF(SIGN(参与者填写!CK3-参与者填写!CL3)=SIGN(比赛赛程!F31-比赛赛程!G31),1,0)),"") | AF3: =IF(AND(参与者填写!CN3<>"",参与者填写!CO3<>""),IF(AND(参与者填写!CN3=比赛赛程!F32,参与者填写!CO3=比赛赛程!G32),4,IF(SIGN(参与者填写!CN3-参与者填写!CO3)=SIGN(比赛赛程!F32-比赛赛程!G32),1,0)),"") | AG3: =IF(AND(参与者填写!CQ3<>"",参与者填写!CR3<>""),IF(AND(参与者填写!CQ3=比赛赛程!F33,参与者填写!CR3=比赛赛程!G33),4,IF(SIGN(参与者填写!CQ3-参与者填写!CR3)=SIGN(比赛赛程!F33-比赛赛程!G33),1,0)),"") | AH3: =IF(AND(参与者填写!CT3<>"",参与者填写!CU3<>""),IF(AND(参与者填写!CT3=比赛赛程!F34,参与者填写!CU3=比赛赛程!G34),4,IF(SIGN(参与者填写!CT3-参与者填写!CU3)=SIGN(比赛赛程!F34-比赛赛程!G34),1,0)),"") | AI3: =IF(AND(参与者填写!CW3<>"",参与者填写!CX3<>""),IF(AND(参与者填写!CW3=比赛赛程!F35,参与者填写!CX3=比赛赛程!G35),4,IF(SIGN(参与者填写!CW3-参与者填写!CX3)=SIGN(比赛赛程!F35-比赛赛程!G35),1,0)),"") | AJ3: =IF(AND(参与者填写!CZ3<>"",参与者填写!DA3<>""),IF(AND(参与者填写!CZ3=比赛赛程!F36,参与者填写!DA3=比赛赛程!G36),4,IF(SIGN(参与者填写!CZ3-参与者填写!DA3)=SIGN(比赛赛程!F36-比赛赛程!G36),1,0)),"") | AK3: =IF(AND(参与者填写!DC3<>"",参与者填写!DD3<>""),IF(AND(参与者填写!DC3=比赛赛程!F37,参与者填写!DD3=比赛赛程!G37),4,IF(SIGN(参与者填写!DC3-参与者填写!DD3)=SIGN(比赛赛程!F37-比赛赛程!G37),1,0)),"") | AL3: =IF(AND(参与者填写!DF3<>"",参与者填写!DG3<>""),IF(AND(参与者填写!DF3=比赛赛程!F38,参与者填写!DG3=比赛赛程!G38),4,IF(SIGN(参与者填写!DF3-参与者填写!DG3)=SIGN(比赛赛程!F38-比赛赛程!G38),1,0)),"") | AM3: =IF(AND(参与者填写!DI3<>"",参与者填写!DJ3<>""),IF(AND(参与者填写!DI3=比赛赛程!F39,参与者填写!DJ3=比赛赛程!G39),4,IF(SIGN(参与者填写!DI3-参与者填写!DJ3)=SIGN(比赛赛程!F39-比赛赛程!G39),1,0)),"") | AN3: =IF(AND(参与者填写!DL3<>"",参与者填写!DM3<>""),IF(AND(参与者填写!DL3=比赛赛程!F40,参与者填写!DM3=比赛赛程!G40),4,IF(SIGN(参与者填写!DL3-参与者填写!DM3)=SIGN(比赛赛程!F40-比赛赛程!G40),1,0)),"") | AO3: =IF(AND(参与者填写!DO3<>"",参与者填写!DP3<>""),IF(AND(参与者填写!DO3=比赛赛程!F41,参与者填写!DP3=比赛赛程!G41),4,IF(SIGN(参与者填写!DO3-参与者填写!DP3)=SIGN(比赛赛程!F41-比赛赛程!G41),1,0)),"") | AP3: =IF(AND(参与者填写!DR3<>"",参与者填写!DS3<>""),IF(AND(参与者填写!DR3=比赛赛程!F42,参与者填写!DS3=比赛赛程!G42),4,IF(SIGN(参与者填写!DR3-参与者填写!DS3)=SIGN(比赛赛程!F42-比赛赛程!G42),1,0)),"") | AQ3: =IF(AND(参与者填写!DU3<>"",参与者填写!DV3<>""),IF(AND(参与者填写!DU3=比赛赛程!F43,参与者填写!DV3=比赛赛程!G43),4,IF(SIGN(参与者填写!DU3-参与者填写!DV3)=SIGN(比赛赛程!F43-比赛赛程!G43),1,0)),"") | AR3: =IF(AND(参与者填写!DX3<>"",参与者填写!DY3<>""),IF(AND(参与者填写!DX3=比赛赛程!F44,参与者填写!DY3=比赛赛程!G44),4,IF(SIGN(参与者填写!DX3-参与者填写!DY3)=SIGN(比赛赛程!F44-比赛赛程!G44),1,0)),"") | AS3: =IF(AND(参与者填写!EA3<>"",参与者填写!EB3<>""),IF(AND(参与者填写!EA3=比赛赛程!F45,参与者填写!EB3=比赛赛程!G45),4,IF(SIGN(参与者填写!EA3-参与者填写!EB3)=SIGN(比赛赛程!F45-比赛赛程!G45),1,0)),"") | AT3: =IF(AND(参与者填写!ED3<>"",参与者填写!EE3<>""),IF(AND(参与者填写!ED3=比赛赛程!F46,参与者填写!EE3=比赛赛程!G46),4,IF(SIGN(参与者填写!ED3-参与者填写!EE3)=SIGN(比赛赛程!F46-比赛赛程!G46),1,0)),"") | AU3: =IF(AND(参与者填写!EG3<>"",参与者填写!EH3<>""),IF(AND(参与者填写!EG3=比赛赛程!F47,参与者填写!EH3=比赛赛程!G47),4,IF(SIGN(参与者填写!EG3-参与者填写!EH3)=SIGN(比赛赛程!F47-比赛赛程!G47),1,0)),"") | AV3: =IF(AND(参与者填写!EJ3<>"",参与者填写!EK3<>""),IF(AND(参与者填写!EJ3=比赛赛程!F48,参与者填写!EK3=比赛赛程!G48),4,IF(SIGN(参与者填写!EJ3-参与者填写!EK3)=SIGN(比赛赛程!F48-比赛赛程!G48),1,0)),"") | AW3: =IF(AND(参与者填写!EM3<>"",参与者填写!EN3<>""),IF(AND(参与者填写!EM3=比赛赛程!F49,参与者填写!EN3=比赛赛程!G49),4,IF(SIGN(参与者填写!EM3-参与者填写!EN3)=SIGN(比赛赛程!F49-比赛赛程!G49),1,0)),"") | AX3: =IF(AND(参与者填写!EP3<>"",参与者填写!EQ3<>""),IF(AND(参与者填写!EP3=比赛赛程!F50,参与者填写!EQ3=比赛赛程!G50),4,IF(SIGN(参与者填写!EP3-参与者填写!EQ3)=SIGN(比赛赛程!F50-比赛赛程!G50),1,0)),"") | AY3: =IF(AND(参与者填写!ES3<>"",参与者填写!ET3<>""),IF(AND(参与者填写!ES3=比赛赛程!F51,参与者填写!ET3=比赛赛程!G51),4,IF(SIGN(参与者填写!ES3-参与者填写!ET3)=SIGN(比赛赛程!F51-比赛赛程!G51),1,0)),"") | AZ3: =IF(AND(参与者填写!EV3<>"",参与者填写!EW3<>""),IF(AND(参与者填写!EV3=比赛赛程!F52,参与者填写!EW3=比赛赛程!G52),4,IF(SIGN(参与者填写!EV3-参与者填写!EW3)=SIGN(比赛赛程!F52-比赛赛程!G52),1,0)),"") | BA3: =IF(AND(参与者填写!EY3<>"",参与者填写!EZ3<>""),IF(AND(参与者填写!EY3=比赛赛程!F53,参与者填写!EZ3=比赛赛程!G53),4,IF(SIGN(参与者填写!EY3-参与者填写!EZ3)=SIGN(比赛赛程!F53-比赛赛程!G53),1,0)),"") | BB3: =IF(AND(参与者填写!FB3<>"",参与者填写!FC3<>""),IF(AND(参与者填写!FB3=比赛赛程!F54,参与者填写!FC3=比赛赛程!G54),4,IF(SIGN(参与者填写!FB3-参与者填写!FC3)=SIGN(比赛赛程!F54-比赛赛程!G54),1,0)),"") | BC3: =IF(AND(参与者填写!FE3<>"",参与者填写!FF3<>""),IF(AND(参与者填写!FE3=比赛赛程!F55,参与者填写!FF3=比赛赛程!G55),4,IF(SIGN(参与者填写!FE3-参与者填写!FF3)=SIGN(比赛赛程!F55-比赛赛程!G55),1,0)),"") | BD3: =IF(AND(参与者填写!FH3<>"",参与者填写!FI3<>""),IF(AND(参与者填写!FH3=比赛赛程!F56,参与者填写!FI3=比赛赛程!G56),4,IF(SIGN(参与者填写!FH3-参与者填写!FI3)=SIGN(比赛赛程!F56-比赛赛程!G56),1,0)),"") | BE3: =IF(AND(参与者填写!FK3<>"",参与者填写!FL3<>""),IF(AND(参与者填写!FK3=比赛赛程!F57,参与者填写!FL3=比赛赛程!G57),4,IF(SIGN(参与者填写!FK3-参与者填写!FL3)=SIGN(比赛赛程!F57-比赛赛程!G57),1,0)),"") | BF3: =IF(AND(参与者填写!FN3<>"",参与者填写!FO3<>""),IF(AND(参与者填写!FN3=比赛赛程!F58,参与者填写!FO3=比赛赛程!G58),4,IF(SIGN(参与者填写!FN3-参与者填写!FO3)=SIGN(比赛赛程!F58-比赛赛程!G58),1,0)),"") | BG3: =IF(AND(参与者填写!FQ3<>"",参与者填写!FR3<>""),IF(AND(参与者填写!FQ3=比赛赛程!F59,参与者填写!FR3=比赛赛程!G59),4,IF(SIGN(参与者填写!FQ3-参与者填写!FR3)=SIGN(比赛赛程!F59-比赛赛程!G59),1,0)),"") | BH3: =IF(AND(参与者填写!FT3<>"",参与者填写!FU3<>""),IF(AND(参与者填写!FT3=比赛赛程!F60,参与者填写!FU3=比赛赛程!G60),4,IF(SIGN(参与者填写!FT3-参与者填写!FU3)=SIGN(比赛赛程!F60-比赛赛程!G60),1,0)),"") | BI3: =IF(AND(参与者填写!FW3<>"",参与者填写!FX3<>""),IF(AND(参与者填写!FW3=比赛赛程!F61,参与者填写!FX3=比赛赛程!G61),4,IF(SIGN(参与者填写!FW3-参与者填写!FX3)=SIGN(比赛赛程!F61-比赛赛程!G61),1,0)),"") | BJ3: =IF(AND(参与者填写!FZ3<>"",参与者填写!GA3<>""),IF(AND(参与者填写!FZ3=比赛赛程!F62,参与者填写!GA3=比赛赛程!G62),4,IF(SIGN(参与者填写!FZ3-参与者填写!GA3)=SIGN(比赛赛程!F62-比赛赛程!G62),1,0)),"") | BK3: =IF(AND(参与者填写!GC3<>"",参与者填写!GD3<>""),IF(AND(参与者填写!GC3=比赛赛程!F63,参与者填写!GD3=比赛赛程!G63),4,IF(SIGN(参与者填写!GC3-参与者填写!GD3)=SIGN(比赛赛程!F63-比赛赛程!G63),1,0)),"") | BL3: =IF(AND(参与者填写!GF3<>"",参与者填写!GG3<>""),IF(AND(参与者填写!GF3=比赛赛程!F64,参与者填写!GG3=比赛赛程!G64),4,IF(SIGN(参与者填写!GF3-参与者填写!GG3)=SIGN(比赛赛程!F64-比赛赛程!G64),1,0)),"") | BM3: =IF(AND(参与者填写!GI3<>"",参与者填写!GJ3<>""),IF(AND(参与者填写!GI3=比赛赛程!F65,参与者填写!GJ3=比赛赛程!G65),4,IF(SIGN(参与者填写!GI3-参与者填写!GJ3)=SIGN(比赛赛程!F65-比赛赛程!G65),1,0)),"") | BN3: =IF(AND(参与者填写!GL3<>"",参与者填写!GM3<>""),IF(AND(参与者填写!GL3=比赛赛程!F66,参与者填写!GM3=比赛赛程!G66),4,IF(SIGN(参与者填写!GL3-参与者填写!GM3)=SIGN(比赛赛程!F66-比赛赛程!G66),1,0)),"") | BO3: =IF(AND(参与者填写!GO3<>"",参与者填写!GP3<>""),IF(AND(参与者填写!GO3=比赛赛程!F67,参与者填写!GP3=比赛赛程!G67),4,IF(SIGN(参与者填写!GO3-参与者填写!GP3)=SIGN(比赛赛程!F67-比赛赛程!G67),1,0)),"") | BP3: =IF(AND(参与者填写!GR3<>"",参与者填写!GS3<>""),IF(AND(参与者填写!GR3=比赛赛程!F68,参与者填写!GS3=比赛赛程!G68),4,IF(SIGN(参与者填写!GR3-参与者填写!GS3)=SIGN(比赛赛程!F68-比赛赛程!G68),1,0)),"") | BQ3: =IF(AND(参与者填写!GU3<>"",参与者填写!GV3<>""),IF(AND(参与者填写!GU3=比赛赛程!F69,参与者填写!GV3=比赛赛程!G69),4,IF(SIGN(参与者填写!GU3-参与者填写!GV3)=SIGN(比赛赛程!F69-比赛赛程!G69),1,0)),"") | BR3: =IF(AND(参与者填写!GX3<>"",参与者填写!GY3<>""),IF(AND(参与者填写!GX3=比赛赛程!F70,参与者填写!GY3=比赛赛程!G70),4,IF(SIGN(参与者填写!GX3-参与者填写!GY3)=SIGN(比赛赛程!F70-比赛赛程!G70),1,0)),"") | BS3: =IF(AND(参与者填写!HA3<>"",参与者填写!HB3<>""),IF(AND(参与者填写!HA3=比赛赛程!F71,参与者填写!HB3=比赛赛程!G71),4,IF(SIGN(参与者填写!HA3-参与者填写!HB3)=SIGN(比赛赛程!F71-比赛赛程!G71),1,0)),"") | BT3: =IF(AND(参与者填写!HD3<>"",参与者填写!HE3<>""),IF(AND(参与者填写!HD3=比赛赛程!F72,参与者填写!HE3=比赛赛程!G72),4,IF(SIGN(参与者填写!HD3-参与者填写!HE3)=SIGN(比赛赛程!F72-比赛赛程!G72),1,0)),"") | BU3: =IF(AND(参与者填写!HG3<>"",参与者填写!HH3<>""),IF(AND(参与者填写!HG3=比赛赛程!F73,参与者填写!HH3=比赛赛程!G73),4,IF(SIGN(参与者填写!HG3-参与者填写!HH3)=SIGN(比赛赛程!F73-比赛赛程!G73),1,0)),"") | BV3: =IF(AND(参与者填写!HJ3<>"",参与者填写!HK3<>""),IF(AND(参与者填写!HJ3=比赛赛程!F74,参与者填写!HK3=比赛赛程!G74),4,IF(SIGN(参与者填写!HJ3-参与者填写!HK3)=SIGN(比赛赛程!F74-比赛赛程!G74),1,0)),"") | BW3: =IF(AND(参与者填写!HM3<>"",参与者填写!HN3<>""),IF(AND(参与者填写!HM3=比赛赛程!F75,参与者填写!HN3=比赛赛程!G75),4,IF(SIGN(参与者填写!HM3-参与者填写!HN3)=SIGN(比赛赛程!F75-比赛赛程!G75),1,0)),"") | BX3: =IF(AND(参与者填写!HP3<>"",参与者填写!HQ3<>""),IF(AND(参与者填写!HP3=比赛赛程!F76,参与者填写!HQ3=比赛赛程!G76),4,IF(SIGN(参与者填写!HP3-参与者填写!HQ3)=SIGN(比赛赛程!F76-比赛赛程!G76),1,0)),"") | BY3: =IF(AND(参与者填写!HS3<>"",参与者填写!HT3<>""),IF(AND(参与者填写!HS3=比赛赛程!F77,参与者填写!HT3=比赛赛程!G77),4,IF(SIGN(参与者填写!HS3-参与者填写!HT3)=SIGN(比赛赛程!F77-比赛赛程!G77),1,0)),"") | BZ3: =IF(AND(参与者填写!HV3<>"",参与者填写!HW3<>""),IF(AND(参与者填写!HV3=比赛赛程!F78,参与者填写!HW3=比赛赛程!G78),4,IF(SIGN(参与者填写!HV3-参与者填写!HW3)=SIGN(比赛赛程!F78-比赛赛程!G78),1,0)),"") | CA3: =IF(AND(参与者填写!HY3<>"",参与者填写!HZ3<>""),IF(AND(参与者填写!HY3=比赛赛程!F79,参与者填写!HZ3=比赛赛程!G79),4,IF(SIGN(参与者填写!HY3-参与者填写!HZ3)=SIGN(比赛赛程!F79-比赛赛程!G79),1,0)),"") | CB3: =IF(AND(参与者填写!IB3<>"",参与者填写!IC3<>""),IF(AND(参与者填写!IB3=比赛赛程!F80,参与者填写!IC3=比赛赛程!G80),4,IF(SIGN(参与者填写!IB3-参与者填写!IC3)=SIGN(比赛赛程!F80-比赛赛程!G80),1,0)),"") | CC3: =IF(AND(参与者填写!IE3<>"",参与者填写!IF3<>""),IF(AND(参与者填写!IE3=比赛赛程!F81,参与者填写!IF3=比赛赛程!G81),4,IF(SIGN(参与者填写!IE3-参与者填写!IF3)=SIGN(比赛赛程!F81-比赛赛程!G81),1,0)),"") | CD3: =IF(AND(参与者填写!IH3<>"",参与者填写!II3<>""),IF(AND(参与者填写!IH3=比赛赛程!F82,参与者填写!II3=比赛赛程!G82),4,IF(SIGN(参与者填写!IH3-参与者填写!II3)=SIGN(比赛赛程!F82-比赛赛程!G82),1,0)),"") | CE3: =IF(AND(参与者填写!IK3<>"",参与者填写!IL3<>""),IF(AND(参与者填写!IK3=比赛赛程!F83,参与者填写!IL3=比赛赛程!G83),4,IF(SIGN(参与者填写!IK3-参与者填写!IL3)=SIGN(比赛赛程!F83-比赛赛程!G83),1,0)),"") | CF3: =IF(AND(参与者填写!IN3<>"",参与者填写!IO3<>""),IF(AND(参与者填写!IN3=比赛赛程!F84,参与者填写!IO3=比赛赛程!G84),4,IF(SIGN(参与者填写!IN3-参与者填写!IO3)=SIGN(比赛赛程!F84-比赛赛程!G84),1,0)),"") | CG3: =IF(AND(参与者填写!IQ3<>"",参与者填写!IR3<>""),IF(AND(参与者填写!IQ3=比赛赛程!F85,参与者填写!IR3=比赛赛程!G85),4,IF(SIGN(参与者填写!IQ3-参与者填写!IR3)=SIGN(比赛赛程!F85-比赛赛程!G85),1,0)),"") | CH3: =IF(AND(参与者填写!IT3<>"",参与者填写!IU3<>""),IF(AND(参与者填写!IT3=比赛赛程!F86,参与者填写!IU3=比赛赛程!G86),4,IF(SIGN(参与者填写!IT3-参与者填写!IU3)=SIGN(比赛赛程!F86-比赛赛程!G86),1,0)),"") | CI3: =IF(AND(参与者填写!IW3<>"",参与者填写!IX3<>""),IF(AND(参与者填写!IW3=比赛赛程!F87,参与者填写!IX3=比赛赛程!G87),4,IF(SIGN(参与者填写!IW3-参与者填写!IX3)=SIGN(比赛赛程!F87-比赛赛程!G87),1,0)),"") | CJ3: =IF(AND(参与者填写!IZ3<>"",参与者填写!JA3<>""),IF(AND(参与者填写!IZ3=比赛赛程!F88,参与者填写!JA3=比赛赛程!G88),4,IF(SIGN(参与者填写!IZ3-参与者填写!JA3)=SIGN(比赛赛程!F88-比赛赛程!G88),1,0)),"") | CK3: =IF(AND(参与者填写!JC3<>"",参与者填写!JD3<>""),IF(AND(参与者填写!JC3=比赛赛程!F89,参与者填写!JD3=比赛赛程!G89),4,IF(SIGN(参与者填写!JC3-参与者填写!JD3)=SIGN(比赛赛程!F89-比赛赛程!G89),1,0)),"") | CL3: =IF(AND(参与者填写!JF3<>"",参与者填写!JG3<>""),IF(AND(参与者填写!JF3=比赛赛程!F90,参与者填写!JG3=比赛赛程!G90),4,IF(SIGN(参与者填写!JF3-参与者填写!JG3)=SIGN(比赛赛程!F90-比赛赛程!G90),1,0)),"") | CM3: =IF(AND(参与者填写!JI3<>"",参与者填写!JJ3<>""),IF(AND(参与者填写!JI3=比赛赛程!F91,参与者填写!JJ3=比赛赛程!G91),4,IF(SIGN(参与者填写!JI3-参与者填写!JJ3)=SIGN(比赛赛程!F91-比赛赛程!G91),1,0)),"") | CN3: =IF(AND(参与者填写!JL3<>"",参与者填写!JM3<>""),IF(AND(参与者填写!JL3=比赛赛程!F92,参与者填写!JM3=比赛赛程!G92),4,IF(SIGN(参与者填写!JL3-参与者填写!JM3)=SIGN(比赛赛程!F92-比赛赛程!G92),1,0)),"") | CO3: =IF(AND(参与者填写!JO3<>"",参与者填写!JP3<>""),IF(AND(参与者填写!JO3=比赛赛程!F93,参与者填写!JP3=比赛赛程!G93),4,IF(SIGN(参与者填写!JO3-参与者填写!JP3)=SIGN(比赛赛程!F93-比赛赛程!G93),1,0)),"") | CP3: =IF(AND(参与者填写!JR3<>"",参与者填写!JS3<>""),IF(AND(参与者填写!JR3=比赛赛程!F94,参与者填写!JS3=比赛赛程!G94),4,IF(SIGN(参与者填写!JR3-参与者填写!JS3)=SIGN(比赛赛程!F94-比赛赛程!G94),1,0)),"") | CQ3: =IF(AND(参与者填写!JU3<>"",参与者填写!JV3<>""),IF(AND(参与者填写!JU3=比赛赛程!F95,参与者填写!JV3=比赛赛程!G95),4,IF(SIGN(参与者填写!JU3-参与者填写!JV3)=SIGN(比赛赛程!F95-比赛赛程!G95),1,0)),"") | CR3: =IF(AND(参与者填写!JX3<>"",参与者填写!JY3<>""),IF(AND(参与者填写!JX3=比赛赛程!F96,参与者填写!JY3=比赛赛程!G96),4,IF(SIGN(参与者填写!JX3-参与者填写!JY3)=SIGN(比赛赛程!F96-比赛赛程!G96),1,0)),"") | CS3: =IF(AND(参与者填写!KA3<>"",参与者填写!KB3<>""),IF(AND(参与者填写!KA3=比赛赛程!F97,参与者填写!KB3=比赛赛程!G97),4,IF(SIGN(参与者填写!KA3-参与者填写!KB3)=SIGN(比赛赛程!F97-比赛赛程!G97),1,0)),"") | CT3: =IF(AND(参与者填写!KD3<>"",参与者填写!KE3<>""),IF(AND(参与者填写!KD3=比赛赛程!F98,参与者填写!KE3=比赛赛程!G98),4,IF(SIGN(参与者填写!KD3-参与者填写!KE3)=SIGN(比赛赛程!F98-比赛赛程!G98),1,0)),"") | CU3: =IF(AND(参与者填写!KG3<>"",参与者填写!KH3<>""),IF(AND(参与者填写!KG3=比赛赛程!F99,参与者填写!KH3=比赛赛程!G99),4,IF(SIGN(参与者填写!KG3-参与者填写!KH3)=SIGN(比赛赛程!F99-比赛赛程!G99),1,0)),"") | CV3: =IF(AND(参与者填写!KJ3<>"",参与者填写!KK3<>""),IF(AND(参与者填写!KJ3=比赛赛程!F100,参与者填写!KK3=比赛赛程!G100),4,IF(SIGN(参与者填写!KJ3-参与者填写!KK3)=SIGN(比赛赛程!F100-比赛赛程!G100),1,0)),"") | CW3: =IF(AND(参与者填写!KM3<>"",参与者填写!KN3<>""),IF(AND(参与者填写!KM3=比赛赛程!F101,参与者填写!KN3=比赛赛程!G101),4,IF(SIGN(参与者填写!KM3-参与者填写!KN3)=SIGN(比赛赛程!F101-比赛赛程!G101),1,0)),"") | CX3: =IF(AND(参与者填写!KP3<>"",参与者填写!KQ3<>""),IF(AND(参与者填写!KP3=比赛赛程!F102,参与者填写!KQ3=比赛赛程!G102),4,IF(SIGN(参与者填写!KP3-参与者填写!KQ3)=SIGN(比赛赛程!F102-比赛赛程!G102),1,0)),"") | CY3: =IF(AND(参与者填写!KS3<>"",参与者填写!KT3<>""),IF(AND(参与者填写!KS3=比赛赛程!F103,参与者填写!KT3=比赛赛程!G103),4,IF(SIGN(参与者填写!KS3-参与者填写!KT3)=SIGN(比赛赛程!F103-比赛赛程!G103),1,0)),"") | CZ3: =IF(AND(参与者填写!KV3<>"",参与者填写!KW3<>""),IF(AND(参与者填写!KV3=比赛赛程!F104,参与者填写!KW3=比赛赛程!G104),4,IF(SIGN(参与者填写!KV3-参与者填写!KW3)=SIGN(比赛赛程!F104-比赛赛程!G104),1,0)),"") | DA3: =IF(AND(参与者填写!KY3<>"",参与者填写!KZ3<>""),IF(AND(参与者填写!KY3=比赛赛程!F105,参与者填写!KZ3=比赛赛程!G105),4,IF(SIGN(参与者填写!KY3-参与者填写!KZ3)=SIGN(比赛赛程!F105-比赛赛程!G105),1,0)),"")
A4: 王五 | B4: =IF(AND(参与者填写!B4<>"",参与者填写!C4<>""),IF(AND(参与者填写!B4=比赛赛程!F2,参与者填写!C4=比赛赛程!G2),4,IF(SIGN(参与者填写!B4-参与者填写!C4)=SIGN(比赛赛程!F2-比赛赛程!G2),1,0)),"") -> 0 | C4: =IF(AND(参与者填写!E4<>"",参与者填写!F4<>""),IF(AND(参与者填写!E4=比赛赛程!F3,参与者填写!F4=比赛赛程!G3),4,IF(SIGN(参与者填写!E4-参与者填写!F4)=SIGN(比赛赛程!F3-比赛赛程!G3),1,0)),"") -> 0 | D4: =IF(AND(参与者填写!H4<>"",参与者填写!I4<>""),IF(AND(参与者填写!H4=比赛赛程!F4,参与者填写!I4=比赛赛程!G4),4,IF(SIGN(参与者填写!H4-参与者填写!I4)=SIGN(比赛赛程!F4-比赛赛程!G4),1,0)),"") -> 0 | E4: =IF(AND(参与者填写!K4<>"",参与者填写!L4<>""),IF(AND(参与者填写!K4=比赛赛程!F5,参与者填写!L4=比赛赛程!G5),4,IF(SIGN(参与者填写!K4-参与者填写!L4)=SIGN(比赛赛程!F5-比赛赛程!G5),1,0)),"") -> 4 | F4: =IF(AND(参与者填写!N4<>"",参与者填写!O4<>""),IF(AND(参与者填写!N4=比赛赛程!F6,参与者填写!O4=比赛赛程!G6),4,IF(SIGN(参与者填写!N4-参与者填写!O4)=SIGN(比赛赛程!F6-比赛赛程!G6),1,0)),"") -> 1 | G4: =IF(AND(参与者填写!Q4<>"",参与者填写!R4<>""),IF(AND(参与者填写!Q4=比赛赛程!F7,参与者填写!R4=比赛赛程!G7),4,IF(SIGN(参与者填写!Q4-参与者填写!R4)=SIGN(比赛赛程!F7-比赛赛程!G7),1,0)),"") -> 0 | H4: =IF(AND(参与者填写!T4<>"",参与者填写!U4<>""),IF(AND(参与者填写!T4=比赛赛程!F8,参与者填写!U4=比赛赛程!G8),4,IF(SIGN(参与者填写!T4-参与者填写!U4)=SIGN(比赛赛程!F8-比赛赛程!G8),1,0)),"") -> 0 | I4: =IF(AND(参与者填写!W4<>"",参与者填写!X4<>""),IF(AND(参与者填写!W4=比赛赛程!F9,参与者填写!X4=比赛赛程!G9),4,IF(SIGN(参与者填写!W4-参与者填写!X4)=SIGN(比赛赛程!F9-比赛赛程!G9),1,0)),"") -> 0 | J4: =IF(AND(参与者填写!Z4<>"",参与者填写!AA4<>""),IF(AND(参与者填写!Z4=比赛赛程!F10,参与者填写!AA4=比赛赛程!G10),4,IF(SIGN(参与者填写!Z4-参与者填写!AA4)=SIGN(比赛赛程!F10-比赛赛程!G10),1,0)),"") -> 1 | K4: =IF(AND(参与者填写!AC4<>"",参与者填写!AD4<>""),IF(AND(参与者填写!AC4=比赛赛程!F11,参与者填写!AD4=比赛赛程!G11),4,IF(SIGN(参与者填写!AC4-参与者填写!AD4)=SIGN(比赛赛程!F11-比赛赛程!G11),1,0)),"") -> 0 | L4: =IF(AND(参与者填写!AF4<>"",参与者填写!AG4<>""),IF(AND(参与者填写!AF4=比赛赛程!F12,参与者填写!AG4=比赛赛程!G12),4,IF(SIGN(参与者填写!AF4-参与者填写!AG4)=SIGN(比赛赛程!F12-比赛赛程!G12),1,0)),"") -> 0 | M4: =IF(AND(参与者填写!AI4<>"",参与者填写!AJ4<>""),IF(AND(参与者填写!AI4=比赛赛程!F13,参与者填写!AJ4=比赛赛程!G13),4,IF(SIGN(参与者填写!AI4-参与者填写!AJ4)=SIGN(比赛赛程!F13-比赛赛程!G13),1,0)),"") -> 0 | N4: =IF(AND(参与者填写!AL4<>"",参与者填写!AM4<>""),IF(AND(参与者填写!AL4=比赛赛程!F14,参与者填写!AM4=比赛赛程!G14),4,IF(SIGN(参与者填写!AL4-参与者填写!AM4)=SIGN(比赛赛程!F14-比赛赛程!G14),1,0)),"") -> 0 | O4: =IF(AND(参与者填写!AO4<>"",参与者填写!AP4<>""),IF(AND(参与者填写!AO4=比赛赛程!F15,参与者填写!AP4=比赛赛程!G15),4,IF(SIGN(参与者填写!AO4-参与者填写!AP4)=SIGN(比赛赛程!F15-比赛赛程!G15),1,0)),"") -> 0 | P4: =IF(AND(参与者填写!AR4<>"",参与者填写!AS4<>""),IF(AND(参与者填写!AR4=比赛赛程!F16,参与者填写!AS4=比赛赛程!G16),4,IF(SIGN(参与者填写!AR4-参与者填写!AS4)=SIGN(比赛赛程!F16-比赛赛程!G16),1,0)),"") -> 0 | Q4: =IF(AND(参与者填写!AU4<>"",参与者填写!AV4<>""),IF(AND(参与者填写!AU4=比赛赛程!F17,参与者填写!AV4=比赛赛程!G17),4,IF(SIGN(参与者填写!AU4-参与者填写!AV4)=SIGN(比赛赛程!F17-比赛赛程!G17),1,0)),"") -> 0 | R4: =IF(AND(参与者填写!AX4<>"",参与者填写!AY4<>""),IF(AND(参与者填写!AX4=比赛赛程!F18,参与者填写!AY4=比赛赛程!G18),4,IF(SIGN(参与者填写!AX4-参与者填写!AY4)=SIGN(比赛赛程!F18-比赛赛程!G18),1,0)),"") -> 0 | S4: =IF(AND(参与者填写!BA4<>"",参与者填写!BB4<>""),IF(AND(参与者填写!BA4=比赛赛程!F19,参与者填写!BB4=比赛赛程!G19),4,IF(SIGN(参与者填写!BA4-参与者填写!BB4)=SIGN(比赛赛程!F19-比赛赛程!G19),1,0)),"") -> 0 | T4: =IF(AND(参与者填写!BD4<>"",参与者填写!BE4<>""),IF(AND(参与者填写!BD4=比赛赛程!F20,参与者填写!BE4=比赛赛程!G20),4,IF(SIGN(参与者填写!BD4-参与者填写!BE4)=SIGN(比赛赛程!F20-比赛赛程!G20),1,0)),"") -> 1 | U4: =IF(AND(参与者填写!BG4<>"",参与者填写!BH4<>""),IF(AND(参与者填写!BG4=比赛赛程!F21,参与者填写!BH4=比赛赛程!G21),4,IF(SIGN(参与者填写!BG4-参与者填写!BH4)=SIGN(比赛赛程!F21-比赛赛程!G21),1,0)),"") -> 1 | V4: =IF(AND(参与者填写!BJ4<>"",参与者填写!BK4<>""),IF(AND(参与者填写!BJ4=比赛赛程!F22,参与者填写!BK4=比赛赛程!G22),4,IF(SIGN(参与者填写!BJ4-参与者填写!BK4)=SIGN(比赛赛程!F22-比赛赛程!G22),1,0)),"") | W4: =IF(AND(参与者填写!BM4<>"",参与者填写!BN4<>""),IF(AND(参与者填写!BM4=比赛赛程!F23,参与者填写!BN4=比赛赛程!G23),4,IF(SIGN(参与者填写!BM4-参与者填写!BN4)=SIGN(比赛赛程!F23-比赛赛程!G23),1,0)),"") | X4: =IF(AND(参与者填写!BP4<>"",参与者填写!BQ4<>""),IF(AND(参与者填写!BP4=比赛赛程!F24,参与者填写!BQ4=比赛赛程!G24),4,IF(SIGN(参与者填写!BP4-参与者填写!BQ4)=SIGN(比赛赛程!F24-比赛赛程!G24),1,0)),"") | Y4: =IF(AND(参与者填写!BS4<>"",参与者填写!BT4<>""),IF(AND(参与者填写!BS4=比赛赛程!F25,参与者填写!BT4=比赛赛程!G25),4,IF(SIGN(参与者填写!BS4-参与者填写!BT4)=SIGN(比赛赛程!F25-比赛赛程!G25),1,0)),"") | Z4: =IF(AND(参与者填写!BV4<>"",参与者填写!BW4<>""),IF(AND(参与者填写!BV4=比赛赛程!F26,参与者填写!BW4=比赛赛程!G26),4,IF(SIGN(参与者填写!BV4-参与者填写!BW4)=SIGN(比赛赛程!F26-比赛赛程!G26),1,0)),"") | AA4: =IF(AND(参与者填写!BY4<>"",参与者填写!BZ4<>""),IF(AND(参与者填写!BY4=比赛赛程!F27,参与者填写!BZ4=比赛赛程!G27),4,IF(SIGN(参与者填写!BY4-参与者填写!BZ4)=SIGN(比赛赛程!F27-比赛赛程!G27),1,0)),"") | AB4: =IF(AND(参与者填写!CB4<>"",参与者填写!CC4<>""),IF(AND(参与者填写!CB4=比赛赛程!F28,参与者填写!CC4=比赛赛程!G28),4,IF(SIGN(参与者填写!CB4-参与者填写!CC4)=SIGN(比赛赛程!F28-比赛赛程!G28),1,0)),"") | AC4: =IF(AND(参与者填写!CE4<>"",参与者填写!CF4<>""),IF(AND(参与者填写!CE4=比赛赛程!F29,参与者填写!CF4=比赛赛程!G29),4,IF(SIGN(参与者填写!CE4-参与者填写!CF4)=SIGN(比赛赛程!F29-比赛赛程!G29),1,0)),"") | AD4: =IF(AND(参与者填写!CH4<>"",参与者填写!CI4<>""),IF(AND(参与者填写!CH4=比赛赛程!F30,参与者填写!CI4=比赛赛程!G30),4,IF(SIGN(参与者填写!CH4-参与者填写!CI4)=SIGN(比赛赛程!F30-比赛赛程!G30),1,0)),"") | AE4: =IF(AND(参与者填写!CK4<>"",参与者填写!CL4<>""),IF(AND(参与者填写!CK4=比赛赛程!F31,参与者填写!CL4=比赛赛程!G31),4,IF(SIGN(参与者填写!CK4-参与者填写!CL4)=SIGN(比赛赛程!F31-比赛赛程!G31),1,0)),"") | AF4: =IF(AND(参与者填写!CN4<>"",参与者填写!CO4<>""),IF(AND(参与者填写!CN4=比赛赛程!F32,参与者填写!CO4=比赛赛程!G32),4,IF(SIGN(参与者填写!CN4-参与者填写!CO4)=SIGN(比赛赛程!F32-比赛赛程!G32),1,0)),"") | AG4: =IF(AND(参与者填写!CQ4<>"",参与者填写!CR4<>""),IF(AND(参与者填写!CQ4=比赛赛程!F33,参与者填写!CR4=比赛赛程!G33),4,IF(SIGN(参与者填写!CQ4-参与者填写!CR4)=SIGN(比赛赛程!F33-比赛赛程!G33),1,0)),"") | AH4: =IF(AND(参与者填写!CT4<>"",参与者填写!CU4<>""),IF(AND(参与者填写!CT4=比赛赛程!F34,参与者填写!CU4=比赛赛程!G34),4,IF(SIGN(参与者填写!CT4-参与者填写!CU4)=SIGN(比赛赛程!F34-比赛赛程!G34),1,0)),"") | AI4: =IF(AND(参与者填写!CW4<>"",参与者填写!CX4<>""),IF(AND(参与者填写!CW4=比赛赛程!F35,参与者填写!CX4=比赛赛程!G35),4,IF(SIGN(参与者填写!CW4-参与者填写!CX4)=SIGN(比赛赛程!F35-比赛赛程!G35),1,0)),"") | AJ4: =IF(AND(参与者填写!CZ4<>"",参与者填写!DA4<>""),IF(AND(参与者填写!CZ4=比赛赛程!F36,参与者填写!DA4=比赛赛程!G36),4,IF(SIGN(参与者填写!CZ4-参与者填写!DA4)=SIGN(比赛赛程!F36-比赛赛程!G36),1,0)),"") | AK4: =IF(AND(参与者填写!DC4<>"",参与者填写!DD4<>""),IF(AND(参与者填写!DC4=比赛赛程!F37,参与者填写!DD4=比赛赛程!G37),4,IF(SIGN(参与者填写!DC4-参与者填写!DD4)=SIGN(比赛赛程!F37-比赛赛程!G37),1,0)),"") | AL4: =IF(AND(参与者填写!DF4<>"",参与者填写!DG4<>""),IF(AND(参与者填写!DF4=比赛赛程!F38,参与者填写!DG4=比赛赛程!G38),4,IF(SIGN(参与者填写!DF4-参与者填写!DG4)=SIGN(比赛赛程!F38-比赛赛程!G38),1,0)),"") | AM4: =IF(AND(参与者填写!DI4<>"",参与者填写!DJ4<>""),IF(AND(参与者填写!DI4=比赛赛程!F39,参与者填写!DJ4=比赛赛程!G39),4,IF(SIGN(参与者填写!DI4-参与者填写!DJ4)=SIGN(比赛赛程!F39-比赛赛程!G39),1,0)),"") | AN4: =IF(AND(参与者填写!DL4<>"",参与者填写!DM4<>""),IF(AND(参与者填写!DL4=比赛赛程!F40,参与者填写!DM4=比赛赛程!G40),4,IF(SIGN(参与者填写!DL4-参与者填写!DM4)=SIGN(比赛赛程!F40-比赛赛程!G40),1,0)),"") | AO4: =IF(AND(参与者填写!DO4<>"",参与者填写!DP4<>""),IF(AND(参与者填写!DO4=比赛赛程!F41,参与者填写!DP4=比赛赛程!G41),4,IF(SIGN(参与者填写!DO4-参与者填写!DP4)=SIGN(比赛赛程!F41-比赛赛程!G41),1,0)),"") | AP4: =IF(AND(参与者填写!DR4<>"",参与者填写!DS4<>""),IF(AND(参与者填写!DR4=比赛赛程!F42,参与者填写!DS4=比赛赛程!G42),4,IF(SIGN(参与者填写!DR4-参与者填写!DS4)=SIGN(比赛赛程!F42-比赛赛程!G42),1,0)),"") | AQ4: =IF(AND(参与者填写!DU4<>"",参与者填写!DV4<>""),IF(AND(参与者填写!DU4=比赛赛程!F43,参与者填写!DV4=比赛赛程!G43),4,IF(SIGN(参与者填写!DU4-参与者填写!DV4)=SIGN(比赛赛程!F43-比赛赛程!G43),1,0)),"") | AR4: =IF(AND(参与者填写!DX4<>"",参与者填写!DY4<>""),IF(AND(参与者填写!DX4=比赛赛程!F44,参与者填写!DY4=比赛赛程!G44),4,IF(SIGN(参与者填写!DX4-参与者填写!DY4)=SIGN(比赛赛程!F44-比赛赛程!G44),1,0)),"") | AS4: =IF(AND(参与者填写!EA4<>"",参与者填写!EB4<>""),IF(AND(参与者填写!EA4=比赛赛程!F45,参与者填写!EB4=比赛赛程!G45),4,IF(SIGN(参与者填写!EA4-参与者填写!EB4)=SIGN(比赛赛程!F45-比赛赛程!G45),1,0)),"") | AT4: =IF(AND(参与者填写!ED4<>"",参与者填写!EE4<>""),IF(AND(参与者填写!ED4=比赛赛程!F46,参与者填写!EE4=比赛赛程!G46),4,IF(SIGN(参与者填写!ED4-参与者填写!EE4)=SIGN(比赛赛程!F46-比赛赛程!G46),1,0)),"") | AU4: =IF(AND(参与者填写!EG4<>"",参与者填写!EH4<>""),IF(AND(参与者填写!EG4=比赛赛程!F47,参与者填写!EH4=比赛赛程!G47),4,IF(SIGN(参与者填写!EG4-参与者填写!EH4)=SIGN(比赛赛程!F47-比赛赛程!G47),1,0)),"") | AV4: =IF(AND(参与者填写!EJ4<>"",参与者填写!EK4<>""),IF(AND(参与者填写!EJ4=比赛赛程!F48,参与者填写!EK4=比赛赛程!G48),4,IF(SIGN(参与者填写!EJ4-参与者填写!EK4)=SIGN(比赛赛程!F48-比赛赛程!G48),1,0)),"") | AW4: =IF(AND(参与者填写!EM4<>"",参与者填写!EN4<>""),IF(AND(参与者填写!EM4=比赛赛程!F49,参与者填写!EN4=比赛赛程!G49),4,IF(SIGN(参与者填写!EM4-参与者填写!EN4)=SIGN(比赛赛程!F49-比赛赛程!G49),1,0)),"") | AX4: =IF(AND(参与者填写!EP4<>"",参与者填写!EQ4<>""),IF(AND(参与者填写!EP4=比赛赛程!F50,参与者填写!EQ4=比赛赛程!G50),4,IF(SIGN(参与者填写!EP4-参与者填写!EQ4)=SIGN(比赛赛程!F50-比赛赛程!G50),1,0)),"") | AY4: =IF(AND(参与者填写!ES4<>"",参与者填写!ET4<>""),IF(AND(参与者填写!ES4=比赛赛程!F51,参与者填写!ET4=比赛赛程!G51),4,IF(SIGN(参与者填写!ES4-参与者填写!ET4)=SIGN(比赛赛程!F51-比赛赛程!G51),1,0)),"") | AZ4: =IF(AND(参与者填写!EV4<>"",参与者填写!EW4<>""),IF(AND(参与者填写!EV4=比赛赛程!F52,参与者填写!EW4=比赛赛程!G52),4,IF(SIGN(参与者填写!EV4-参与者填写!EW4)=SIGN(比赛赛程!F52-比赛赛程!G52),1,0)),"") | BA4: =IF(AND(参与者填写!EY4<>"",参与者填写!EZ4<>""),IF(AND(参与者填写!EY4=比赛赛程!F53,参与者填写!EZ4=比赛赛程!G53),4,IF(SIGN(参与者填写!EY4-参与者填写!EZ4)=SIGN(比赛赛程!F53-比赛赛程!G53),1,0)),"") | BB4: =IF(AND(参与者填写!FB4<>"",参与者填写!FC4<>""),IF(AND(参与者填写!FB4=比赛赛程!F54,参与者填写!FC4=比赛赛程!G54),4,IF(SIGN(参与者填写!FB4-参与者填写!FC4)=SIGN(比赛赛程!F54-比赛赛程!G54),1,0)),"") | BC4: =IF(AND(参与者填写!FE4<>"",参与者填写!FF4<>""),IF(AND(参与者填写!FE4=比赛赛程!F55,参与者填写!FF4=比赛赛程!G55),4,IF(SIGN(参与者填写!FE4-参与者填写!FF4)=SIGN(比赛赛程!F55-比赛赛程!G55),1,0)),"") | BD4: =IF(AND(参与者填写!FH4<>"",参与者填写!FI4<>""),IF(AND(参与者填写!FH4=比赛赛程!F56,参与者填写!FI4=比赛赛程!G56),4,IF(SIGN(参与者填写!FH4-参与者填写!FI4)=SIGN(比赛赛程!F56-比赛赛程!G56),1,0)),"") | BE4: =IF(AND(参与者填写!FK4<>"",参与者填写!FL4<>""),IF(AND(参与者填写!FK4=比赛赛程!F57,参与者填写!FL4=比赛赛程!G57),4,IF(SIGN(参与者填写!FK4-参与者填写!FL4)=SIGN(比赛赛程!F57-比赛赛程!G57),1,0)),"") | BF4: =IF(AND(参与者填写!FN4<>"",参与者填写!FO4<>""),IF(AND(参与者填写!FN4=比赛赛程!F58,参与者填写!FO4=比赛赛程!G58),4,IF(SIGN(参与者填写!FN4-参与者填写!FO4)=SIGN(比赛赛程!F58-比赛赛程!G58),1,0)),"") | BG4: =IF(AND(参与者填写!FQ4<>"",参与者填写!FR4<>""),IF(AND(参与者填写!FQ4=比赛赛程!F59,参与者填写!FR4=比赛赛程!G59),4,IF(SIGN(参与者填写!FQ4-参与者填写!FR4)=SIGN(比赛赛程!F59-比赛赛程!G59),1,0)),"") | BH4: =IF(AND(参与者填写!FT4<>"",参与者填写!FU4<>""),IF(AND(参与者填写!FT4=比赛赛程!F60,参与者填写!FU4=比赛赛程!G60),4,IF(SIGN(参与者填写!FT4-参与者填写!FU4)=SIGN(比赛赛程!F60-比赛赛程!G60),1,0)),"") | BI4: =IF(AND(参与者填写!FW4<>"",参与者填写!FX4<>""),IF(AND(参与者填写!FW4=比赛赛程!F61,参与者填写!FX4=比赛赛程!G61),4,IF(SIGN(参与者填写!FW4-参与者填写!FX4)=SIGN(比赛赛程!F61-比赛赛程!G61),1,0)),"") | BJ4: =IF(AND(参与者填写!FZ4<>"",参与者填写!GA4<>""),IF(AND(参与者填写!FZ4=比赛赛程!F62,参与者填写!GA4=比赛赛程!G62),4,IF(SIGN(参与者填写!FZ4-参与者填写!GA4)=SIGN(比赛赛程!F62-比赛赛程!G62),1,0)),"") | BK4: =IF(AND(参与者填写!GC4<>"",参与者填写!GD4<>""),IF(AND(参与者填写!GC4=比赛赛程!F63,参与者填写!GD4=比赛赛程!G63),4,IF(SIGN(参与者填写!GC4-参与者填写!GD4)=SIGN(比赛赛程!F63-比赛赛程!G63),1,0)),"") | BL4: =IF(AND(参与者填写!GF4<>"",参与者填写!GG4<>""),IF(AND(参与者填写!GF4=比赛赛程!F64,参与者填写!GG4=比赛赛程!G64),4,IF(SIGN(参与者填写!GF4-参与者填写!GG4)=SIGN(比赛赛程!F64-比赛赛程!G64),1,0)),"") | BM4: =IF(AND(参与者填写!GI4<>"",参与者填写!GJ4<>""),IF(AND(参与者填写!GI4=比赛赛程!F65,参与者填写!GJ4=比赛赛程!G65),4,IF(SIGN(参与者填写!GI4-参与者填写!GJ4)=SIGN(比赛赛程!F65-比赛赛程!G65),1,0)),"") | BN4: =IF(AND(参与者填写!GL4<>"",参与者填写!GM4<>""),IF(AND(参与者填写!GL4=比赛赛程!F66,参与者填写!GM4=比赛赛程!G66),4,IF(SIGN(参与者填写!GL4-参与者填写!GM4)=SIGN(比赛赛程!F66-比赛赛程!G66),1,0)),"") | BO4: =IF(AND(参与者填写!GO4<>"",参与者填写!GP4<>""),IF(AND(参与者填写!GO4=比赛赛程!F67,参与者填写!GP4=比赛赛程!G67),4,IF(SIGN(参与者填写!GO4-参与者填写!GP4)=SIGN(比赛赛程!F67-比赛赛程!G67),1,0)),"") | BP4: =IF(AND(参与者填写!GR4<>"",参与者填写!GS4<>""),IF(AND(参与者填写!GR4=比赛赛程!F68,参与者填写!GS4=比赛赛程!G68),4,IF(SIGN(参与者填写!GR4-参与者填写!GS4)=SIGN(比赛赛程!F68-比赛赛程!G68),1,0)),"") | BQ4: =IF(AND(参与者填写!GU4<>"",参与者填写!GV4<>""),IF(AND(参与者填写!GU4=比赛赛程!F69,参与者填写!GV4=比赛赛程!G69),4,IF(SIGN(参与者填写!GU4-参与者填写!GV4)=SIGN(比赛赛程!F69-比赛赛程!G69),1,0)),"") | BR4: =IF(AND(参与者填写!GX4<>"",参与者填写!GY4<>""),IF(AND(参与者填写!GX4=比赛赛程!F70,参与者填写!GY4=比赛赛程!G70),4,IF(SIGN(参与者填写!GX4-参与者填写!GY4)=SIGN(比赛赛程!F70-比赛赛程!G70),1,0)),"") | BS4: =IF(AND(参与者填写!HA4<>"",参与者填写!HB4<>""),IF(AND(参与者填写!HA4=比赛赛程!F71,参与者填写!HB4=比赛赛程!G71),4,IF(SIGN(参与者填写!HA4-参与者填写!HB4)=SIGN(比赛赛程!F71-比赛赛程!G71),1,0)),"") | BT4: =IF(AND(参与者填写!HD4<>"",参与者填写!HE4<>""),IF(AND(参与者填写!HD4=比赛赛程!F72,参与者填写!HE4=比赛赛程!G72),4,IF(SIGN(参与者填写!HD4-参与者填写!HE4)=SIGN(比赛赛程!F72-比赛赛程!G72),1,0)),"") | BU4: =IF(AND(参与者填写!HG4<>"",参与者填写!HH4<>""),IF(AND(参与者填写!HG4=比赛赛程!F73,参与者填写!HH4=比赛赛程!G73),4,IF(SIGN(参与者填写!HG4-参与者填写!HH4)=SIGN(比赛赛程!F73-比赛赛程!G73),1,0)),"") | BV4: =IF(AND(参与者填写!HJ4<>"",参与者填写!HK4<>""),IF(AND(参与者填写!HJ4=比赛赛程!F74,参与者填写!HK4=比赛赛程!G74),4,IF(SIGN(参与者填写!HJ4-参与者填写!HK4)=SIGN(比赛赛程!F74-比赛赛程!G74),1,0)),"") | BW4: =IF(AND(参与者填写!HM4<>"",参与者填写!HN4<>""),IF(AND(参与者填写!HM4=比赛赛程!F75,参与者填写!HN4=比赛赛程!G75),4,IF(SIGN(参与者填写!HM4-参与者填写!HN4)=SIGN(比赛赛程!F75-比赛赛程!G75),1,0)),"") | BX4: =IF(AND(参与者填写!HP4<>"",参与者填写!HQ4<>""),IF(AND(参与者填写!HP4=比赛赛程!F76,参与者填写!HQ4=比赛赛程!G76),4,IF(SIGN(参与者填写!HP4-参与者填写!HQ4)=SIGN(比赛赛程!F76-比赛赛程!G76),1,0)),"") | BY4: =IF(AND(参与者填写!HS4<>"",参与者填写!HT4<>""),IF(AND(参与者填写!HS4=比赛赛程!F77,参与者填写!HT4=比赛赛程!G77),4,IF(SIGN(参与者填写!HS4-参与者填写!HT4)=SIGN(比赛赛程!F77-比赛赛程!G77),1,0)),"") | BZ4: =IF(AND(参与者填写!HV4<>"",参与者填写!HW4<>""),IF(AND(参与者填写!HV4=比赛赛程!F78,参与者填写!HW4=比赛赛程!G78),4,IF(SIGN(参与者填写!HV4-参与者填写!HW4)=SIGN(比赛赛程!F78-比赛赛程!G78),1,0)),"") | CA4: =IF(AND(参与者填写!HY4<>"",参与者填写!HZ4<>""),IF(AND(参与者填写!HY4=比赛赛程!F79,参与者填写!HZ4=比赛赛程!G79),4,IF(SIGN(参与者填写!HY4-参与者填写!HZ4)=SIGN(比赛赛程!F79-比赛赛程!G79),1,0)),"") | CB4: =IF(AND(参与者填写!IB4<>"",参与者填写!IC4<>""),IF(AND(参与者填写!IB4=比赛赛程!F80,参与者填写!IC4=比赛赛程!G80),4,IF(SIGN(参与者填写!IB4-参与者填写!IC4)=SIGN(比赛赛程!F80-比赛赛程!G80),1,0)),"") | CC4: =IF(AND(参与者填写!IE4<>"",参与者填写!IF4<>""),IF(AND(参与者填写!IE4=比赛赛程!F81,参与者填写!IF4=比赛赛程!G81),4,IF(SIGN(参与者填写!IE4-参与者填写!IF4)=SIGN(比赛赛程!F81-比赛赛程!G81),1,0)),"") | CD4: =IF(AND(参与者填写!IH4<>"",参与者填写!II4<>""),IF(AND(参与者填写!IH4=比赛赛程!F82,参与者填写!II4=比赛赛程!G82),4,IF(SIGN(参与者填写!IH4-参与者填写!II4)=SIGN(比赛赛程!F82-比赛赛程!G82),1,0)),"") | CE4: =IF(AND(参与者填写!IK4<>"",参与者填写!IL4<>""),IF(AND(参与者填写!IK4=比赛赛程!F83,参与者填写!IL4=比赛赛程!G83),4,IF(SIGN(参与者填写!IK4-参与者填写!IL4)=SIGN(比赛赛程!F83-比赛赛程!G83),1,0)),"") | CF4: =IF(AND(参与者填写!IN4<>"",参与者填写!IO4<>""),IF(AND(参与者填写!IN4=比赛赛程!F84,参与者填写!IO4=比赛赛程!G84),4,IF(SIGN(参与者填写!IN4-参与者填写!IO4)=SIGN(比赛赛程!F84-比赛赛程!G84),1,0)),"") | CG4: =IF(AND(参与者填写!IQ4<>"",参与者填写!IR4<>""),IF(AND(参与者填写!IQ4=比赛赛程!F85,参与者填写!IR4=比赛赛程!G85),4,IF(SIGN(参与者填写!IQ4-参与者填写!IR4)=SIGN(比赛赛程!F85-比赛赛程!G85),1,0)),"") | CH4: =IF(AND(参与者填写!IT4<>"",参与者填写!IU4<>""),IF(AND(参与者填写!IT4=比赛赛程!F86,参与者填写!IU4=比赛赛程!G86),4,IF(SIGN(参与者填写!IT4-参与者填写!IU4)=SIGN(比赛赛程!F86-比赛赛程!G86),1,0)),"") | CI4: =IF(AND(参与者填写!IW4<>"",参与者填写!IX4<>""),IF(AND(参与者填写!IW4=比赛赛程!F87,参与者填写!IX4=比赛赛程!G87),4,IF(SIGN(参与者填写!IW4-参与者填写!IX4)=SIGN(比赛赛程!F87-比赛赛程!G87),1,0)),"") | CJ4: =IF(AND(参与者填写!IZ4<>"",参与者填写!JA4<>""),IF(AND(参与者填写!IZ4=比赛赛程!F88,参与者填写!JA4=比赛赛程!G88),4,IF(SIGN(参与者填写!IZ4-参与者填写!JA4)=SIGN(比赛赛程!F88-比赛赛程!G88),1,0)),"") | CK4: =IF(AND(参与者填写!JC4<>"",参与者填写!JD4<>""),IF(AND(参与者填写!JC4=比赛赛程!F89,参与者填写!JD4=比赛赛程!G89),4,IF(SIGN(参与者填写!JC4-参与者填写!JD4)=SIGN(比赛赛程!F89-比赛赛程!G89),1,0)),"") | CL4: =IF(AND(参与者填写!JF4<>"",参与者填写!JG4<>""),IF(AND(参与者填写!JF4=比赛赛程!F90,参与者填写!JG4=比赛赛程!G90),4,IF(SIGN(参与者填写!JF4-参与者填写!JG4)=SIGN(比赛赛程!F90-比赛赛程!G90),1,0)),"") | CM4: =IF(AND(参与者填写!JI4<>"",参与者填写!JJ4<>""),IF(AND(参与者填写!JI4=比赛赛程!F91,参与者填写!JJ4=比赛赛程!G91),4,IF(SIGN(参与者填写!JI4-参与者填写!JJ4)=SIGN(比赛赛程!F91-比赛赛程!G91),1,0)),"") | CN4: =IF(AND(参与者填写!JL4<>"",参与者填写!JM4<>""),IF(AND(参与者填写!JL4=比赛赛程!F92,参与者填写!JM4=比赛赛程!G92),4,IF(SIGN(参与者填写!JL4-参与者填写!JM4)=SIGN(比赛赛程!F92-比赛赛程!G92),1,0)),"") | CO4: =IF(AND(参与者填写!JO4<>"",参与者填写!JP4<>""),IF(AND(参与者填写!JO4=比赛赛程!F93,参与者填写!JP4=比赛赛程!G93),4,IF(SIGN(参与者填写!JO4-参与者填写!JP4)=SIGN(比赛赛程!F93-比赛赛程!G93),1,0)),"") | CP4: =IF(AND(参与者填写!JR4<>"",参与者填写!JS4<>""),IF(AND(参与者填写!JR4=比赛赛程!F94,参与者填写!JS4=比赛赛程!G94),4,IF(SIGN(参与者填写!JR4-参与者填写!JS4)=SIGN(比赛赛程!F94-比赛赛程!G94),1,0)),"") | CQ4: =IF(AND(参与者填写!JU4<>"",参与者填写!JV4<>""),IF(AND(参与者填写!JU4=比赛赛程!F95,参与者填写!JV4=比赛赛程!G95),4,IF(SIGN(参与者填写!JU4-参与者填写!JV4)=SIGN(比赛赛程!F95-比赛赛程!G95),1,0)),"") | CR4: =IF(AND(参与者填写!JX4<>"",参与者填写!JY4<>""),IF(AND(参与者填写!JX4=比赛赛程!F96,参与者填写!JY4=比赛赛程!G96),4,IF(SIGN(参与者填写!JX4-参与者填写!JY4)=SIGN(比赛赛程!F96-比赛赛程!G96),1,0)),"") | CS4: =IF(AND(参与者填写!KA4<>"",参与者填写!KB4<>""),IF(AND(参与者填写!KA4=比赛赛程!F97,参与者填写!KB4=比赛赛程!G97),4,IF(SIGN(参与者填写!KA4-参与者填写!KB4)=SIGN(比赛赛程!F97-比赛赛程!G97),1,0)),"") | CT4: =IF(AND(参与者填写!KD4<>"",参与者填写!KE4<>""),IF(AND(参与者填写!KD4=比赛赛程!F98,参与者填写!KE4=比赛赛程!G98),4,IF(SIGN(参与者填写!KD4-参与者填写!KE4)=SIGN(比赛赛程!F98-比赛赛程!G98),1,0)),"") | CU4: =IF(AND(参与者填写!KG4<>"",参与者填写!KH4<>""),IF(AND(参与者填写!KG4=比赛赛程!F99,参与者填写!KH4=比赛赛程!G99),4,IF(SIGN(参与者填写!KG4-参与者填写!KH4)=SIGN(比赛赛程!F99-比赛赛程!G99),1,0)),"") | CV4: =IF(AND(参与者填写!KJ4<>"",参与者填写!KK4<>""),IF(AND(参与者填写!KJ4=比赛赛程!F100,参与者填写!KK4=比赛赛程!G100),4,IF(SIGN(参与者填写!KJ4-参与者填写!KK4)=SIGN(比赛赛程!F100-比赛赛程!G100),1,0)),"") | CW4: =IF(AND(参与者填写!KM4<>"",参与者填写!KN4<>""),IF(AND(参与者填写!KM4=比赛赛程!F101,参与者填写!KN4=比赛赛程!G101),4,IF(SIGN(参与者填写!KM4-参与者填写!KN4)=SIGN(比赛赛程!F101-比赛赛程!G101),1,0)),"") | CX4: =IF(AND(参与者填写!KP4<>"",参与者填写!KQ4<>""),IF(AND(参与者填写!KP4=比赛赛程!F102,参与者填写!KQ4=比赛赛程!G102),4,IF(SIGN(参与者填写!KP4-参与者填写!KQ4)=SIGN(比赛赛程!F102-比赛赛程!G102),1,0)),"") | CY4: =IF(AND(参与者填写!KS4<>"",参与者填写!KT4<>""),IF(AND(参与者填写!KS4=比赛赛程!F103,参与者填写!KT4=比赛赛程!G103),4,IF(SIGN(参与者填写!KS4-参与者填写!KT4)=SIGN(比赛赛程!F103-比赛赛程!G103),1,0)),"") | CZ4: =IF(AND(参与者填写!KV4<>"",参与者填写!KW4<>""),IF(AND(参与者填写!KV4=比赛赛程!F104,参与者填写!KW4=比赛赛程!G104),4,IF(SIGN(参与者填写!KV4-参与者填写!KW4)=SIGN(比赛赛程!F104-比赛赛程!G104),1,0)),"") | DA4: =IF(AND(参与者填写!KY4<>"",参与者填写!KZ4<>""),IF(AND(参与者填写!KY4=比赛赛程!F105,参与者填写!KZ4=比赛赛程!G105),4,IF(SIGN(参与者填写!KY4-参与者填写!KZ4)=SIGN(比赛赛程!F105-比赛赛程!G105),1,0)),"")
